Workbook
Name DATA: #REF!
Name DATA: #REF!
Name DATA: #REF!
Name DATA: #REF!
Name DATA: #REF!
Name DATA: #REF!
Name DATA: #REF!
Name DATA: #REF!
Name DATA: #REF!
Name DATA: #REF!
Name DATA: #REF!
Name ㅇㅇ: #REF!
Name ㅇㅇ: #REF!
Name ㅗㅗㅗ: #REF!
Name ㅗㅗㅗ: #REF!
Name ㅗㅗㅗ: #REF!
Name ㅗㅗㅗ: #REF!
Name ㅗㅗㅗ: #REF!
Name ㅗㅗㅗ: #REF!
Name ㅗㅗㅗ: #REF!
Name ㅗㅗㅗ: #REF!
Name ㅗㅗㅗ: #REF!
Name ㅗㅗㅗ: #REF!

Sheet 11월 에너지 (2)
A1: 18년 11월 ENERGY 실적
B2: 반 | E2: Heat | F2: M1 | H2: M2 | J2: R | L2: 계 | N2: 원단위 | R2: 출강량 | S2: Lanma 산소 | X2: VLB 및 Burner 산소 | AC2: 산소계 | AE2: VLB 및 Burner 연료
F3: 시간 | G3: 전력 | H3: 시간 | I3: 전력 | J3: 시간 | K3: 전력 | L3: 시간 | M3: 전력 | N3: M1 | O3: M2 | P3: R | Q3: 계 | S3: M1 | T3: M2 | U3: R | V3: 계 | W3: 원단위 | X3: M1 | Y3: M2 | Z3: R | AA3: 계 | AB3: 원단위 | AC3: 사용량 | AD3: 원단위 | AE3: M1 | AF3: M2 | AG3: R | AH3: 계 | AI3: 원단위
B4: A | E4: =COUNTIF(B$14:B$789,B4) -> 207 | F4: =IF(E4=0,"",SUMIF($B$14:$B$960,$B4,F$14:F$960)/$E4) -> 15.193237 | G4: =IF(E4=0,"",SUMIF($B$14:$B$960,$B4,G$14:G$960)/$E4) -> 17385.99 | H4: =IF(E4=0,"",SUMIF($B$14:$B$960,$B4,H$14:H$960)/$E4) -> 12.352657 | I4: =IF(E4=0,"",SUMIF($B$14:$B$960,$B4,I$14:I$960)/$E4) -> 14615.942 | J4: =IF(E4=0,"",SUMIF($B$14:$B$960,$B4,J$14:J$960)/$E4) -> 6.0048309 | K4: =IF(E4=0,"",SUMIF($B$14:$B$960,$B4,K$14:K$960)/$E4) -> 7647.343 | L4: =IF(E4=0,"",SUMIF($B$14:$B$960,$B4,L$14:L$960)/$E4) -> 33.550725 | M4: =IF(E4=0,"",SUMIF($B$14:$B$960,$B4,M$14:M$960)/$E4) -> 39649.275 | N4: =IF(E4=0,"",SUMIF($B$14:$B$960,$B4,N$14:N$960)/$E4) -> 119.47889 | O4: =IF(E4=0,"",SUMIF($B$14:$B$960,$B4,O$14:O$960)/$E4) -> 99.974539 | P4: =IF(E4=0,"",SUMIF($B$14:$B$960,$B4,P$14:P$960)/$E4) -> 52.683362 | Q4: =IF($E4=0,"",SUMIF($B$14:$B$960,$B4,Q$14:Q$960)/$E4) -> 272.13679 | R4: =IF(ISERROR(SUMIF($B$14:$B$960,$B4,R$14:R$960)/$E4),"",(SUMIF($B$14:$B$960,$B4,R$14:R$960)/$E4)) -> 106.39372 | S4: =IF(E4=0,"",SUMIF($B$14:$B$960,$B4,S$14:S$960)/$E4) -> 0.62318841 | T4: =IF(E4=0,"",SUMIF($B$14:$B$960,$B4,T$14:T$960)/$E4) -> 106.42995 | U4: =IF(E4=0,"",SUMIF($B$14:$B$960,$B4,U$14:U$960)/$E4) -> 157.31401 | V4: =IF(E4=0,"",SUMIF($B$14:$B$960,$B4,V$14:V$960)/$E4) -> 264.36715 | W4: =IF(E4=0,"",SUMIF($B$14:$B$960,$B4,W$14:W$960)/$E4) -> 1.8159829 | X4: =IF(E4=0,"",SUMIF($B$14:$B$960,$B4,X$14:X$960)/$E4) -> 1264.8309 | Y4: =IF(E4=0,"",SUMIF($B$14:$B$960,$B4,Y$14:Y$960)/$E4) -> 1156.1449 | Z4: =IF(E4=0,"",SUMIF($B$14:$B$960,$B4,Z$14:Z$960)/$E4) -> 621.42995 | AA4: =IF(E4=0,"",SUMIF($B$14:$B$960,$B4,AA$14:AA$960)/$E4) -> 3042.4058 | AB4: =IF(E4=0,"",SUMIF($B$14:$B$960,$B4,AB$14:AB$960)/$E4) -> 20.884555 | AC4: =IF(E4=0,"",SUMIF($B$14:$B$960,$B4,AC$14:AC$960)/$E4) -> 3306.7729 | AD4: =IF(E4=0,"",SUMIF($B$14:$B$960,$B4,AD$14:AD$960)/$E4) -> 22.700538 | AE4: =IF(E4=0,"",SUMIF($B$14:$B$960,$B4,AE$14:AE$960)/$E4) -> 18.763285 | AF4: =IF(E4=0,"",SUMIF($B$14:$B$960,$B4,AF$14:AF$960)/$E4) -> 18.483092 | AG4: =IF(E4=0,"",SUMIF($B$14:$B$960,$B4,AG$14:AG$960)/$E4) -> 0.11111111 | AH4: =IF(E4=0,"",SUMIF($B$14:$B$960,$B4,AH$14:AH$960)/$E4) -> 37.357488 | AI4: =IF(E4=0,"",SUMIF($B$14:$B$960,$B4,AI$14:AI$960)/$E4) -> 0.25659558
B5: B | E5: =COUNTIF(B$14:B$789,B5) -> 188 | F5: =IF(E5=0,"",SUMIF($B$14:$B$960,$B5,F$14:F$960)/$E5) -> 15.111702 | G5: =IF(E5=0,"",SUMIF($B$14:$B$960,$B5,G$14:G$960)/$E5) -> 17297.872 | H5: =IF(E5=0,"",SUMIF($B$14:$B$960,$B5,H$14:H$960)/$E5) -> 12.425532 | I5: =IF(E5=0,"",SUMIF($B$14:$B$960,$B5,I$14:I$960)/$E5) -> 14553.564 | J5: =IF(E5=0,"",SUMIF($B$14:$B$960,$B5,J$14:J$960)/$E5) -> 6.3351064 | K5: =IF(E5=0,"",SUMIF($B$14:$B$960,$B5,K$14:K$960)/$E5) -> 8136.1702 | L5: =IF(E5=0,"",SUMIF($B$14:$B$960,$B5,L$14:L$960)/$E5) -> 33.87234 | M5: =IF(E5=0,"",SUMIF($B$14:$B$960,$B5,M$14:M$960)/$E5) -> 39987.606 | N5: =IF(E5=0,"",SUMIF($B$14:$B$960,$B5,N$14:N$960)/$E5) -> 117.4875 | O5: =IF(E5=0,"",SUMIF($B$14:$B$960,$B5,O$14:O$960)/$E5) -> 98.566208 | P5: =IF(E5=0,"",SUMIF($B$14:$B$960,$B5,P$14:P$960)/$E5) -> 55.447756 | Q5: =IF(E5=0,"",SUMIF($B$14:$B$960,$B5,Q$14:Q$960)/$E5) -> 271.50147 | R5: =IF(ISERROR(SUMIF($B$14:$B$960,$B5,R$14:R$960)/$E5),"",(SUMIF($B$14:$B$960,$B5,R$14:R$960)/$E5)) -> 107.43989 | S5: =IF(E5=0,"",SUMIF($B$14:$B$960,$B5,S$14:S$960)/$E5) -> 0 | T5: =IF(E5=0,"",SUMIF($B$14:$B$960,$B5,T$14:T$960)/$E5) -> 108.48936 | U5: =IF(E5=0,"",SUMIF($B$14:$B$960,$B5,U$14:U$960)/$E5) -> 164.92021 | V5: =IF(E5=0,"",SUMIF($B$14:$B$960,$B5,V$14:V$960)/$E5) -> 273.40957 | W5: =IF(E5=0,"",SUMIF($B$14:$B$960,$B5,W$14:W$960)/$E5) -> 1.8573929 | X5: =IF(E5=0,"",SUMIF($B$14:$B$960,$B5,X$14:X$960)/$E5) -> 1266.2128 | Y5: =IF(E5=0,"",SUMIF($B$14:$B$960,$B5,Y$14:Y$960)/$E5) -> 1159.484 | Z5: =IF(E5=0,"",SUMIF($B$14:$B$960,$B5,Z$14:Z$960)/$E5) -> 620.15957 | AA5: =IF(E5=0,"",SUMIF($B$14:$B$960,$B5,AA$14:AA$960)/$E5) -> 3045.8564 | AB5: =IF(E5=0,"",SUMIF($B$14:$B$960,$B5,AB$14:AB$960)/$E5) -> 20.679635 | AC5: =IF(E5=0,"",SUMIF($B$14:$B$960,$B5,AC$14:AC$960)/$E5) -> 3319.266 | AD5: =IF(E5=0,"",SUMIF($B$14:$B$960,$B5,AD$14:AD$960)/$E5) -> 22.537028 | AE5: =IF(E5=0,"",SUMIF($B$14:$B$960,$B5,AE$14:AE$960)/$E5) -> 18.542553 | AF5: =IF(E5=0,"",SUMIF($B$14:$B$960,$B5,AF$14:AF$960)/$E5) -> 18.776596 | AG5: =IF(E5=0,"",SUMIF($B$14:$B$960,$B5,AG$14:AG$960)/$E5) -> 0.35638298 | AH5: =IF(E5=0,"",SUMIF($B$14:$B$960,$B5,AH$14:AH$960)/$E5) -> 37.675532 | AI5: =IF(E5=0,"",SUMIF($B$14:$B$960,$B5,AI$14:AI$960)/$E5) -> 0.25555929
B6: C | E6: =COUNTIF(B$14:B$789,B6) -> 176 | F6: =IF(E6=0,"",SUMIF($B$14:$B$960,$B6,F$14:F$960)/$E6) -> 14.9375 | G6: =IF(E6=0,"",SUMIF($B$14:$B$960,$B6,G$14:G$960)/$E6) -> 17186.245 | H6: =IF(E6=0,"",SUMIF($B$14:$B$960,$B6,H$14:H$960)/$E6) -> 12.761364 | I6: =IF(E6=0,"",SUMIF($B$14:$B$960,$B6,I$14:I$960)/$E6) -> 14947.727 | J6: =IF(E6=0,"",SUMIF($B$14:$B$960,$B6,J$14:J$960)/$E6) -> 5.9147727 | K6: =IF(E6=0,"",SUMIF($B$14:$B$960,$B6,K$14:K$960)/$E6) -> 7426.1364 | L6: =IF(E6=0,"",SUMIF($B$14:$B$960,$B6,L$14:L$960)/$E6) -> 33.613636 | M6: =IF(E6=0,"",SUMIF($B$14:$B$960,$B6,M$14:M$960)/$E6) -> 39560.109 | N6: =IF(E6=0,"",SUMIF($B$14:$B$960,$B6,N$14:N$960)/$E6) -> #DIV/0! | O6: =IF(E6=0,"",SUMIF($B$14:$B$960,$B6,O$14:O$960)/$E6) -> 101.39551 | P6: =IF(E6=0,"",SUMIF($B$14:$B$960,$B6,P$14:P$960)/$E6) -> 50.383359 | Q6: =IF(E6=0,"",SUMIF($B$14:$B$960,$B6,Q$14:Q$960)/$E6) -> 267.0213 | R6: =IF(ISERROR(SUMIF($B$14:$B$960,$B6,R$14:R$960)/$E6),"",(SUMIF($B$14:$B$960,$B6,R$14:R$960)/$E6)) -> 107.23523 | S6: =IF(E6=0,"",SUMIF($B$14:$B$960,$B6,S$14:S$960)/$E6) -> 0 | T6: =IF(E6=0,"",SUMIF($B$14:$B$960,$B6,T$14:T$960)/$E6) -> 103.92045 | U6: =IF(E6=0,"",SUMIF($B$14:$B$960,$B6,U$14:U$960)/$E6) -> 166.25568 | V6: =IF(E6=0,"",SUMIF($B$14:$B$960,$B6,V$14:V$960)/$E6) -> 270.17614 | W6: =IF(E6=0,"",SUMIF($B$14:$B$960,$B6,W$14:W$960)/$E6) -> 1.8322391 | X6: =IF(E6=0,"",SUMIF($B$14:$B$960,$B6,X$14:X$960)/$E6) -> 1255.0284 | Y6: =IF(E6=0,"",SUMIF($B$14:$B$960,$B6,Y$14:Y$960)/$E6) -> 1187.267 | Z6: =IF(E6=0,"",SUMIF($B$14:$B$960,$B6,Z$14:Z$960)/$E6) -> 605.72159 | AA6: =IF(E6=0,"",SUMIF($B$14:$B$960,$B6,AA$14:AA$960)/$E6) -> 3048.017 | AB6: =IF(E6=0,"",SUMIF($B$14:$B$960,$B6,AB$14:AB$960)/$E6) -> 20.677873 | AC6: =IF(E6=0,"",SUMIF($B$14:$B$960,$B6,AC$14:AC$960)/$E6) -> 3318.1932 | AD6: =IF(E6=0,"",SUMIF($B$14:$B$960,$B6,AD$14:AD$960)/$E6) -> 22.510112 | AE6: =IF(E6=0,"",SUMIF($B$14:$B$960,$B6,AE$14:AE$960)/$E6) -> 18.318182 | AF6: =IF(E6=0,"",SUMIF($B$14:$B$960,$B6,AF$14:AF$960)/$E6) -> 19.238636 | AG6: =IF(E6=0,"",SUMIF($B$14:$B$960,$B6,AG$14:AG$960)/$E6) -> 0 | AH6: =IF(E6=0,"",SUMIF($B$14:$B$960,$B6,AH$14:AH$960)/$E6) -> 37.556818 | AI6: =IF(E6=0,"",SUMIF($B$14:$B$960,$B6,AI$14:AI$960)/$E6) -> 0.25479674
B7: D | E7: =COUNTIF(B$14:B$789,B7) -> 193 | F7: =IF(E7=0,"",SUMIF($B$14:$B$960,$B7,F$14:F$960)/$E7) -> 14.632124 | G7: =IF(E7=0,"",SUMIF($B$14:$B$960,$B7,G$14:G$960)/$E7) -> 17012.737 | H7: =IF(E7=0,"",SUMIF($B$14:$B$960,$B7,H$14:H$960)/$E7) -> 12.492228 | I7: =IF(E7=0,"",SUMIF($B$14:$B$960,$B7,I$14:I$960)/$E7) -> 14725.389 | J7: =IF(E7=0,"",SUMIF($B$14:$B$960,$B7,J$14:J$960)/$E7) -> 6.0777202 | K7: =IF(E7=0,"",SUMIF($B$14:$B$960,$B7,K$14:K$960)/$E7) -> 7648.7047 | L7: =IF(E7=0,"",SUMIF($B$14:$B$960,$B7,L$14:L$960)/$E7) -> 33.202073 | M7: =IF(E7=0,"",SUMIF($B$14:$B$960,$B7,M$14:M$960)/$E7) -> 39386.831 | N7: =IF(E7=0,"",SUMIF($B$14:$B$960,$B7,N$14:N$960)/$E7) -> #DIV/0! | O7: =IF(E7=0,"",SUMIF($B$14:$B$960,$B7,O$14:O$960)/$E7) -> 100.04111 | P7: =IF(E7=0,"",SUMIF($B$14:$B$960,$B7,P$14:P$960)/$E7) -> 52.010257 | Q7: =IF(E7=0,"",SUMIF($B$14:$B$960,$B7,Q$14:Q$960)/$E7) -> 265.76046 | R7: =IF(ISERROR(SUMIF($B$14:$B$960,$B7,R$14:R$960)/$E7),"",(SUMIF($B$14:$B$960,$B7,R$14:R$960)/$E7)) -> 105.27979 | S7: =IF(E7=0,"",SUMIF($B$14:$B$960,$B7,S$14:S$960)/$E7) -> 0 | T7: =IF(E7=0,"",SUMIF($B$14:$B$960,$B7,T$14:T$960)/$E7) -> 115.12435 | U7: =IF(E7=0,"",SUMIF($B$14:$B$960,$B7,U$14:U$960)/$E7) -> 144.64767 | V7: =IF(E7=0,"",SUMIF($B$14:$B$960,$B7,V$14:V$960)/$E7) -> 259.77202 | W7: =IF(E7=0,"",SUMIF($B$14:$B$960,$B7,W$14:W$960)/$E7) -> 1.7649268 | X7: =IF(E7=0,"",SUMIF($B$14:$B$960,$B7,X$14:X$960)/$E7) -> 1211.8549 | Y7: =IF(E7=0,"",SUMIF($B$14:$B$960,$B7,Y$14:Y$960)/$E7) -> 1156.9171 | Z7: =IF(E7=0,"",SUMIF($B$14:$B$960,$B7,Z$14:Z$960)/$E7) -> 594.64249 | AA7: =IF(E7=0,"",SUMIF($B$14:$B$960,$B7,AA$14:AA$960)/$E7) -> 2963.4145 | AB7: =IF(E7=0,"",SUMIF($B$14:$B$960,$B7,AB$14:AB$960)/$E7) -> 20.13816 | AC7: =IF(E7=0,"",SUMIF($B$14:$B$960,$B7,AC$14:AC$960)/$E7) -> 3223.1865 | AD7: =IF(E7=0,"",SUMIF($B$14:$B$960,$B7,AD$14:AD$960)/$E7) -> 21.903087 | AE7: =IF(E7=0,"",SUMIF($B$14:$B$960,$B7,AE$14:AE$960)/$E7) -> 18.015544 | AF7: =IF(E7=0,"",SUMIF($B$14:$B$960,$B7,AF$14:AF$960)/$E7) -> 19.067358 | AG7: =IF(E7=0,"",SUMIF($B$14:$B$960,$B7,AG$14:AG$960)/$E7) -> 0.21243523 | AH7: =IF(E7=0,"",SUMIF($B$14:$B$960,$B7,AH$14:AH$960)/$E7) -> 37.295337 | AI7: =IF(E7=0,"",SUMIF($B$14:$B$960,$B7,AI$14:AI$960)/$E7) -> 0.25357061
B8: A로평균 | E8: =COUNTIF(C$14:C$789,"A") -> 385 | F8: =IF($E$8=0,"",SUMIF($C$14:$C$960,"A",F14:F960)/$E$8) -> 14.924675 | G8: =IF($E$8=0,"",SUMIF($C$14:$C$960, "A", G14:G960)/$E$8) -> 17353.401 | H8: =IF(E8=0,"",SUMIF($B$14:$B$960,$B8,H$14:H$960)/$E8) -> 0 | I8: =IF($E$8=0,"",SUMIF($C$14:$C$960, "A", I14:I960)/$E$8) -> 14748.494 | J8: =IF($E$8=0,"",SUMIF($C$14:$C$960,"A",J14:J960)/$E$8) -> 6.2727273 | K8: =IF($E$8=0,"",SUMIF($C$14:$C$960, "A", K14:K960)/$E$8) -> 7913.5065 | L8: =IF($E$8=0,"",SUMIF($C$14:$C$960, "A", L14:L960)/$E$8) -> 33.724675 | M8: =IF($E$8=0,"",SUMIF($C$14:$C$960, "A", M14:M960)/$E$8) -> 40015.401 | N8: =IF($E$8=0,"",SUMIF($C$14:$C$960, "A", N14:N960)/$E$8) -> #DIV/0! | O8: =IF($E$8=0,"",SUMIF($C$14:$C$960, "A", O14:O960)/$E$8) -> 100.21006 | P8: =IF($E$8=0,"",SUMIF($C$14:$C$960, "A", P14:P960)/$E$8) -> 53.92205 | Q8: =IF($E$8=0,"",SUMIF($C$14:$C$960, "A", Q14:Q960)/$E$8) -> 270.6309 | R8: =IF($E$8=0,"",SUMIF($C$14:$C$960,"A",R14:R960)/$E$8) -> 107.01558 | S8: =IF($E$8=0,"",SUMIF($C$14:$C$960, "A", S14:S960)/$E$8) -> 0 | T8: =IF($E$8=0,"",SUMIF($C$14:$C$960, "A", T14:T960)/$E$8) -> 109.31688 | U8: =IF($E$8=0,"",SUMIF($C$14:$C$960, "A", U14:U960)/$E$8) -> 161.15065 | V8: =IF($E$8=0,"",SUMIF($C$14:$C$960, "A", V14:V960)/$E$8) -> 270.46753 | W8: =IF($E$8=0,"",SUMIF($C$14:$C$960, "A", W14:W960)/$E$8) -> 1.840097 | X8: =IF($E$8=0,"",SUMIF($C$14:$C$960, "A", X14:X960)/$E$8) -> 1251.5532 | Y8: =IF($E$8=0,"",SUMIF($C$14:$C$960, "A", Y14:Y960)/$E$8) -> 1168.5455 | Z8: =IF($E$8=0,"",SUMIF($C$14:$C$960, "A", Z14:Z960)/$E$8) -> 627.21299 | ... AI8: =IF($E$8=0,"",SUMIF($C$14:$C$960, "A", AI14:AI960)/$E$8) -> 0.25433922
B9: B로평균 | E9: =COUNTIF(C$14:C$789,"B") -> 379 | F9: =IF($E$9=0,"",SUMIF($C$14:$C$960,"B",F14:F960)/$E$9) -> 15.021108 | G9: =IF($E$9=0,"",SUMIF($C$14:$C$960,"B",G14:G960)/$E$9) -> 17092.555 | H9: =IF(E9=0,"",SUMIF($B$14:$B$960,$B9,H$14:H$960)/$E9) -> 0 | I9: =IF($E$9=0,"",SUMIF($C$14:$C$960,"B",I14:I960)/$E$9) -> 14660.158 | J9: =IF($E$9=0,"",SUMIF($C$14:$C$960,"B",J14:J960)/$E$9) -> 5.8918206 | K9: =IF($E$9=0,"",SUMIF($C$14:$C$960,"B",K14:K960)/$E$9) -> 7517.4142 | L9: =IF($E$9=0,"",SUMIF($C$14:$C$960, "B", L14:L960)/$E$9) -> 33.385224 | M9: =IF($E$9=0,"",SUMIF($C$14:$C$960,"B",M14:M960)/$E$9) -> 39270.127 | N9: =IF($E$9=0,"",SUMIF($C$14:$C$960,"B",N14:N960)/$E$9) -> #DIV/0! | O9: =IF($E$9=0,"",SUMIF($C$14:$C$960,"B",O14:O960)/$E$9) -> 99.730467 | P9: =IF($E$9=0,"",SUMIF($C$14:$C$960,"B",P14:P960)/$E$9) -> 51.385477 | Q9: =IF($E$9=0,"",SUMIF($C$14:$C$960,"B",Q14:Q960)/$E$9) -> 267.72879 | R9: =IF($E$9=0,"",SUMIF($C$14:$C$960,"B",R14:R960)/$E$9) -> 106.10449 | S9: =IF($E$9=0,"",SUMIF($C$14:$C$960,"B",S14:S960)/$E$9) -> 0.34036939 | T9: =IF($E$9=0,"",SUMIF($C$14:$C$960,"B",T14:T960)/$E$9) -> 107.781 | ... AB9: =IF($E$9=0,"",SUMIF($C$14:$C$960,"B",AB14:AB960)/$E$9) -> 20.46611 | AC9: =IF($E$9=0,"",SUMIF($C$14:$C$960, "B", AC14:AC960)/$E$9) -> 3264.5277 | AD9: =IF($E$9=0,"",SUMIF($C$14:$C$960, "B", AD14:AD960)/$E$9) -> 22.259688 | AE9: =IF($E$9=0,"",SUMIF($C$14:$C$960,"B",AE14:AE960)/$E$9) -> 18.477573 | AF9: =IF($E$9=0,"",SUMIF($C$14:$C$960,"B",AF14:AF960)/$E$9) -> 19.002639 | AG9: =IF($E$9=0,"",SUMIF($C$14:$C$960,"B",AG14:AG960)/$E$9) -> 0.060686016 | AH9: =IF($E$9=0,"",SUMIF($C$14:$C$960,"B",AH14:AH960)/$E$9) -> 37.540897 | AI9: =IF($E$9=0,"",SUMIF($C$14:$C$960,"B",AI14:AI960)/$E$9) -> 0.25599785
B10: Total Average | E10: =E8+E9 -> 764 | F10: =IF(F14="","",AVERAGE(F14:F960)) -> 20.647482 | G10: =IF(G14="","",AVERAGE(G14:G960)) -> 23375.905 | H10: =IF(H14="","",AVERAGE(H14:H960)) -> 17.239209 | I10: =IF(I14="","",AVERAGE(I14:I960)) -> 20279.982 | J10: =IF(J14="","",AVERAGE(J14:J960)) -> 8.3938849 | K10: =IF(K14="","",AVERAGE(K14:K960)) -> 10647.482 | L10: =IF(L14="","",AVERAGE(L14:L960)) -> 45.382716 | M10: =IF(M14="","",AVERAGE(M14:M960)) -> 53713.087 | ... Q10: =IF(Q14="","",AVERAGE(Q14:Q960)) -> 371.27507 | R10: =IF(E10="","",AVERAGE(R14:R960)) -> 146.95594 | S10: =IF(S14="","",AVERAGE(S14:S960)) -> 0.23201439 | T10: =IF(T14="","",AVERAGE(T14:T960)) -> 149.86331 | U10: =IF(U14="","",AVERAGE(U14:U960)) -> 217.68885 | V10: =IF(V14="","",AVERAGE(V14:V960)) -> 367.78417 | W10: =IF(W14="","",AVERAGE(W14:W960)) -> 2.5050701 | X10: =IF(X14="","",AVERAGE(X14:X960)) -> 1723.0396 | Y10: =IF(Y14="","",AVERAGE(Y14:Y960)) -> 1605.6978 | Z10: =IF(Z14="","",AVERAGE(Z14:Z960)) -> 842.08633 | ... AI10: =IF(AI14="","",AVERAGE(AI14:AI960)) -> 0.35179735
A12: 월 일 | B12: 반 | C12: 로 | D12: Heat No | E12: 강 종 | F12: M1 | H12: M2 | J12: R | L12: 계 | N12: 원단위 | R12: 출강량 | S12: Lanma 산소 | X12: VLB 및 Burner 산소 | AC12: 산소계 | AE12: VLB 및 Burner 연료
F13: 시간 | G13: 전력 | H13: 시간 | I13: 전력 | J13: 시간 | K13: 전력 | L13: 시간 | M13: 전력 | N13: M1 | O13: M2 | P13: R | Q13: 계 | S13: M1 | T13: M2 | U13: R | V13: 계 | W13: 원단위 | X13: M1 | Y13: M2 | Z13: R | AA13: 계 | AB13: 원단위 | AC13: 사용량 | AD13: 원단위 | AE13: M1 | AF13: M2 | AG13: R | AH13: 계 | AI13: 원단위
A14: =IF('09월 조업일지'!#REF!="","",'09월 조업일지'!#REF!) -> #REF! | B14: ='09월 조업일지'!#REF! -> #REF! | C14: ='09월 조업일지'!#REF! -> #REF! | D14: ='09월 화학성분'!#REF! -> #REF! | E14: SS400-1 | F14: 21 | G14: 23400 | H14: 17 | I14: 20800 | J14: 10 | K14: 12500 | L14: =IF(ISBLANK(F14),"",SUM(F14,H14,J14)) -> 48 | M14: =IF(ISBLANK(G14),"",SUM(G14,I14,K14)) -> 56700 | N14: =IF(ISBLANK(G14),"",G14/R14) -> 160.05472 | O14: =IF(ISBLANK(I14),"",+I14/R14) -> 142.27086 | P14: =IF(ISBLANK(K14),"",K14/R14) -> 85.499316 | Q14: =IF(ISBLANK(K14),"",SUM(N14:P14)) -> 387.8249 | R14: 146.2 | S14: 0 | T14: 197 | U14: 133 | V14: =IF(SUM(S14:U14)=0,"",SUM(S14:U14)) -> 330 | W14: =IF(V14="","",V14/R14) -> 2.2571819 | X14: 1646 | Y14: 1615 | Z14: 945 | AA14: =IF(SUM(X14:Z14)=0,"",SUM(X14:Z14)) -> 4206 | AB14: =IF(AA14="","",AA14/R14) -> 28.76881 | AC14: =IF(SUM(V14,AA14)=0,"",SUM(V14,AA14)) -> 4536 | AD14: =IF(AC14="","",AC14/R14) -> 31.025992 | AE14: 26 | AF14: 23 | AG14: 0 | AH14: =IF(SUM(AE14:AG14)=0,"",SUM(AE14:AG14)) -> 49 | AI14: =IF(AH14="","",AH14/R14) -> 0.33515732
A15: =IF('09월 조업일지'!A12="","",'09월 조업일지'!A12) -> 46266 | B15: ='09월 조업일지'!E12 -> D | C15: ='09월 조업일지'!F12 -> B | D15: ='09월 화학성분'!C12 -> 85214 | E15: =IF(F15="","",E14) -> SS400-1 | F15: 21 | G15: 23600 | H15: 17 | I15: 20600 | J15: 9 | K15: 11300 | L15: =IF(ISBLANK(F15),"",SUM(F15,H15,J15)) -> 47 | M15: =IF(ISBLANK(G15),"",SUM(G15,I15,K15)) -> 55500 | N15: =IF(ISBLANK(G15),"",G15/R15) -> 162.87095 | O15: =IF(ISBLANK(I15),"",+I15/R15) -> 142.16701 | P15: =IF(ISBLANK(K15),"",K15/R15) -> 77.984817 | Q15: =IF(ISBLANK(K15),"",SUM(N15:P15)) -> 383.02277 | R15: 144.9 | S15: 0 | T15: 185 | U15: 150 | V15: =IF(SUM(S15:U15)=0,"",SUM(S15:U15)) -> 335 | W15: =IF(V15="","",V15/R15) -> 2.3119393 | X15: 1603 | Y15: 1578 | Z15: 1014 | AA15: =IF(SUM(X15:Z15)=0,"",SUM(X15:Z15)) -> 4195 | AB15: =IF(AA15="","",AA15/R15) -> 28.951001 | AC15: =IF(SUM(V15,AA15)=0,"",SUM(V15,AA15)) -> 4530 | AD15: =IF(AC15="","",AC15/R15) -> 31.26294 | AE15: 24 | AF15: 28 | AG15: 0 | AH15: =IF(SUM(AE15:AG15)=0,"",SUM(AE15:AG15)) -> 52 | AI15: =IF(AH15="","",AH15/R15) -> 0.35886818
A16: =IF('09월 조업일지'!A13="","",'09월 조업일지'!A13) -> 46266 | B16: ='09월 조업일지'!E13 -> D | C16: ='09월 조업일지'!F13 -> A | D16: ='09월 화학성분'!C13 -> 85215 | E16: =IF(F16="","",E15) -> SS400-1 | F16: 20 | G16: 23300 | H16: 16 | I16: 20400 | J16: 10 | K16: 12900 | L16: =IF(ISBLANK(F16),"",SUM(F16,H16,J16)) -> 46 | M16: =IF(ISBLANK(G16),"",SUM(G16,I16,K16)) -> 56600 | N16: =IF(ISBLANK(G16),"",G16/R16) -> 159.58904 | O16: =IF(ISBLANK(I16),"",+I16/R16) -> 139.72603 | P16: =IF(ISBLANK(K16),"",K16/R16) -> 88.356164 | Q16: =IF(ISBLANK(K16),"",SUM(N16:P16)) -> 387.67123 | R16: 146 | S16: 0 | T16: 207 | U16: 117 | V16: =IF(SUM(S16:U16)=0,"",SUM(S16:U16)) -> 324 | W16: =IF(V16="","",V16/R16) -> 2.2191781 | X16: 1654 | Y16: 1563 | Z16: 1119 | AA16: =IF(SUM(X16:Z16)=0,"",SUM(X16:Z16)) -> 4336 | AB16: =IF(AA16="","",AA16/R16) -> 29.69863 | AC16: =IF(SUM(V16,AA16)=0,"",SUM(V16,AA16)) -> 4660 | AD16: =IF(AC16="","",AC16/R16) -> 31.917808 | AE16: 25 | AF16: 23 | AG16: 0 | AH16: =IF(SUM(AE16:AG16)=0,"",SUM(AE16:AG16)) -> 48 | AI16: =IF(AH16="","",AH16/R16) -> 0.32876712
A17: =IF('09월 조업일지'!A14="","",'09월 조업일지'!A14) -> 46266 | B17: ='09월 조업일지'!E14 -> D | C17: ='09월 조업일지'!F14 -> B | D17: ='09월 화학성분'!C14 -> 85216 | E17: =IF(F17="","",E16) -> SS400-1 | F17: 21 | G17: 23300 | H17: 17 | I17: 20600 | J17: 8 | K17: 10300 | L17: =IF(ISBLANK(F17),"",SUM(F17,H17,J17)) -> 46 | M17: =IF(ISBLANK(G17),"",SUM(G17,I17,K17)) -> 54200 | N17: =IF(ISBLANK(G17),"",G17/R17) -> 159.37073 | O17: =IF(ISBLANK(I17),"",+I17/R17) -> 140.90287 | P17: =IF(ISBLANK(K17),"",K17/R17) -> 70.451436 | Q17: =IF(ISBLANK(K17),"",SUM(N17:P17)) -> 370.72503 | R17: 146.2 | S17: 0 | T17: 195 | U17: 145 | V17: =IF(SUM(S17:U17)=0,"",SUM(S17:U17)) -> 340 | W17: =IF(V17="","",V17/R17) -> 2.3255814 | X17: 1616 | Y17: 1591 | Z17: 739 | AA17: =IF(SUM(X17:Z17)=0,"",SUM(X17:Z17)) -> 3946 | AB17: =IF(AA17="","",AA17/R17) -> 26.990424 | AC17: =IF(SUM(V17,AA17)=0,"",SUM(V17,AA17)) -> 4286 | AD17: =IF(AC17="","",AC17/R17) -> 29.316005 | AE17: 26 | AF17: 30 | AG17: 0 | AH17: =IF(SUM(AE17:AG17)=0,"",SUM(AE17:AG17)) -> 56 | AI17: =IF(AH17="","",AH17/R17) -> 0.38303694
A18: =IF('09월 조업일지'!A15="","",'09월 조업일지'!A15) -> 46266 | B18: ='09월 조업일지'!E15 -> D | C18: ='09월 조업일지'!F15 -> A | D18: ='09월 화학성분'!C15 -> 85217 | E18: =IF(F18="","",E17) -> SS400-1 | F18: 19 | G18: 23400 | H18: 18 | I18: 20700 | J18: 9 | K18: 10700 | L18: =IF(ISBLANK(F18),"",SUM(F18,H18,J18)) -> 46 | M18: =IF(ISBLANK(G18),"",SUM(G18,I18,K18)) -> 54800 | N18: =IF(ISBLANK(G18),"",G18/R18) -> 160.71429 | O18: =IF(ISBLANK(I18),"",+I18/R18) -> 142.17033 | P18: =IF(ISBLANK(K18),"",K18/R18) -> 73.489011 | Q18: =IF(ISBLANK(K18),"",SUM(N18:P18)) -> 376.37363 | R18: 145.6 | S18: 0 | T18: 232 | U18: 148 | V18: =IF(SUM(S18:U18)=0,"",SUM(S18:U18)) -> 380 | W18: =IF(V18="","",V18/R18) -> 2.6098901 | X18: 1660 | Y18: 1581 | Z18: 1149 | AA18: =IF(SUM(X18:Z18)=0,"",SUM(X18:Z18)) -> 4390 | AB18: =IF(AA18="","",AA18/R18) -> 30.151099 | AC18: =IF(SUM(V18,AA18)=0,"",SUM(V18,AA18)) -> 4770 | AD18: =IF(AC18="","",AC18/R18) -> 32.760989 | AE18: 23 | AF18: 25 | AG18: 0 | AH18: =IF(SUM(AE18:AG18)=0,"",SUM(AE18:AG18)) -> 48 | AI18: =IF(AH18="","",AH18/R18) -> 0.32967033
A19: =IF('09월 조업일지'!A16="","",'09월 조업일지'!A16) -> 46266 | B19: ='09월 조업일지'!E16 -> A | C19: ='09월 조업일지'!F16 -> B | D19: ='09월 화학성분'!C16 -> 85218 | E19: =IF(F19="","",E18) -> SS400-1 | F19: 22 | G19: 23600 | H19: 17 | I19: 20600 | J19: 8 | K19: 9800 | L19: =IF(ISBLANK(F19),"",SUM(F19,H19,J19)) -> 47 | M19: =IF(ISBLANK(G19),"",SUM(G19,I19,K19)) -> 54000 | N19: =IF(ISBLANK(G19),"",G19/R19) -> 162.08791 | O19: =IF(ISBLANK(I19),"",+I19/R19) -> 141.48352 | P19: =IF(ISBLANK(K19),"",K19/R19) -> 67.307692 | Q19: =IF(ISBLANK(K19),"",SUM(N19:P19)) -> 370.87912 | R19: 145.6 | S19: 0 | T19: 149 | U19: 209 | V19: =IF(SUM(S19:U19)=0,"",SUM(S19:U19)) -> 358 | W19: =IF(V19="","",V19/R19) -> 2.4587912 | X19: 1767 | Y19: 1605 | Z19: 812 | AA19: =IF(SUM(X19:Z19)=0,"",SUM(X19:Z19)) -> 4184 | AB19: =IF(AA19="","",AA19/R19) -> 28.736264 | AC19: =IF(SUM(V19,AA19)=0,"",SUM(V19,AA19)) -> 4542 | AD19: =IF(AC19="","",AC19/R19) -> 31.195055 | AE19: 27 | AF19: 29 | AG19: 0 | AH19: =IF(SUM(AE19:AG19)=0,"",SUM(AE19:AG19)) -> 56 | AI19: =IF(AH19="","",AH19/R19) -> 0.38461538
A20: =IF('09월 조업일지'!A17="","",'09월 조업일지'!A17) -> 46266 | B20: ='09월 조업일지'!E17 -> A | C20: ='09월 조업일지'!F17 -> A | D20: ='09월 화학성분'!C17 -> 85219 | E20: =IF(F20="","",E19) -> SS400-1 | F20: 20 | G20: 23100 | H20: 16 | I20: 20500 | J20: 6 | K20: 7700 | L20: =IF(ISBLANK(F20),"",SUM(F20,H20,J20)) -> 42 | M20: =IF(ISBLANK(G20),"",SUM(G20,I20,K20)) -> 51300 | N20: =IF(ISBLANK(G20),"",G20/R20) -> 158.43621 | O20: =IF(ISBLANK(I20),"",+I20/R20) -> 140.60357 | P20: =IF(ISBLANK(K20),"",K20/R20) -> 52.812071 | Q20: =IF(ISBLANK(K20),"",SUM(N20:P20)) -> 351.85185 | R20: 145.8 | S20: 0 | T20: 187 | U20: 123 | V20: =IF(SUM(S20:U20)=0,"",SUM(S20:U20)) -> 310 | W20: =IF(V20="","",V20/R20) -> 2.1262003 | X20: 1718 | Y20: 1617 | Z20: 626 | AA20: =IF(SUM(X20:Z20)=0,"",SUM(X20:Z20)) -> 3961 | AB20: =IF(AA20="","",AA20/R20) -> 27.167353 | AC20: =IF(SUM(V20,AA20)=0,"",SUM(V20,AA20)) -> 4271 | AD20: =IF(AC20="","",AC20/R20) -> 29.293553 | AE20: 26 | AF20: 27 | AG20: 0 | AH20: =IF(SUM(AE20:AG20)=0,"",SUM(AE20:AG20)) -> 53 | AI20: =IF(AH20="","",AH20/R20) -> 0.36351166
A21: =IF('09월 조업일지'!A18="","",'09월 조업일지'!A18) -> 46266 | B21: ='09월 조업일지'!E18 -> A | C21: ='09월 조업일지'!F18 -> B | D21: ='09월 화학성분'!C18 -> 85220 | E21: S355JO-01 | F21: 20 | G21: 23600 | H21: 18 | I21: 20600 | J21: 8 | K21: 9600 | L21: =IF(ISBLANK(F21),"",SUM(F21,H21,J21)) -> 46 | M21: =IF(ISBLANK(G21),"",SUM(G21,I21,K21)) -> 53800 | N21: =IF(ISBLANK(G21),"",G21/R21) -> 164.91964 | O21: =IF(ISBLANK(I21),"",+I21/R21) -> 143.95528 | P21: =IF(ISBLANK(K21),"",K21/R21) -> 67.085954 | Q21: =IF(ISBLANK(K21),"",SUM(N21:P21)) -> 375.96087 | R21: 143.1 | S21: 0 | T21: 150 | U21: 190 | V21: =IF(SUM(S21:U21)=0,"",SUM(S21:U21)) -> 340 | W21: =IF(V21="","",V21/R21) -> 2.3759609 | X21: 1585 | Y21: 1711 | Z21: 860 | AA21: =IF(SUM(X21:Z21)=0,"",SUM(X21:Z21)) -> 4156 | AB21: =IF(AA21="","",AA21/R21) -> 29.042628 | AC21: =IF(SUM(V21,AA21)=0,"",SUM(V21,AA21)) -> 4496 | AD21: =IF(AC21="","",AC21/R21) -> 31.418588 | AE21: 21 | AF21: 30 | AG21: 0 | AH21: =IF(SUM(AE21:AG21)=0,"",SUM(AE21:AG21)) -> 51 | AI21: =IF(AH21="","",AH21/R21) -> 0.35639413
A22: =IF('09월 조업일지'!A19="","",'09월 조업일지'!A19) -> 46266 | B22: ='09월 조업일지'!E19 -> A | C22: ='09월 조업일지'!F19 -> A | D22: ='09월 화학성분'!C19 -> 85221 | E22: =IF(F22="","",E21) -> S355JO-01 | F22: 20 | G22: 23300 | H22: 18 | I22: 20500 | J22: 9 | K22: 11300 | L22: =IF(ISBLANK(F22),"",SUM(F22,H22,J22)) -> 47 | M22: =IF(ISBLANK(G22),"",SUM(G22,I22,K22)) -> 55100 | N22: =IF(ISBLANK(G22),"",G22/R22) -> 159.91764 | O22: =IF(ISBLANK(I22),"",+I22/R22) -> 140.70007 | P22: =IF(ISBLANK(K22),"",K22/R22) -> 77.556623 | Q22: =IF(ISBLANK(K22),"",SUM(N22:P22)) -> 378.17433 | R22: 145.7 | S22: 0 | T22: 133 | U22: 185 | V22: =IF(SUM(S22:U22)=0,"",SUM(S22:U22)) -> 318 | W22: =IF(V22="","",V22/R22) -> 2.1825669 | X22: 1665 | Y22: 1630 | Z22: 929 | AA22: =IF(SUM(X22:Z22)=0,"",SUM(X22:Z22)) -> 4224 | AB22: =IF(AA22="","",AA22/R22) -> 28.991078 | AC22: =IF(SUM(V22,AA22)=0,"",SUM(V22,AA22)) -> 4542 | AD22: =IF(AC22="","",AC22/R22) -> 31.173644 | AE22: 26 | AF22: 27 | AG22: 0 | AH22: =IF(SUM(AE22:AG22)=0,"",SUM(AE22:AG22)) -> 53 | AI22: =IF(AH22="","",AH22/R22) -> 0.36376115
A23: =IF('09월 조업일지'!A20="","",'09월 조업일지'!A20) -> 46266 | B23: ='09월 조업일지'!E20 -> A | C23: ='09월 조업일지'!F20 -> B | D23: ='09월 화학성분'!C20 -> 85222 | E23: =IF(F23="","",E22) -> S355JO-01 | F23: 20 | G23: 23700 | H23: 18 | I23: 20200 | J23: 9 | K23: 12400 | L23: =IF(ISBLANK(F23),"",SUM(F23,H23,J23)) -> 47 | M23: =IF(ISBLANK(G23),"",SUM(G23,I23,K23)) -> 56300 | N23: =IF(ISBLANK(G23),"",G23/R23) -> 164.81224 | O23: =IF(ISBLANK(I23),"",+I23/R23) -> 140.47288 | P23: =IF(ISBLANK(K23),"",K23/R23) -> 86.230876 | Q23: =IF(ISBLANK(K23),"",SUM(N23:P23)) -> 391.51599 | R23: 143.8 | S23: 0 | T23: 224 | U23: 180 | V23: =IF(SUM(S23:U23)=0,"",SUM(S23:U23)) -> 404 | W23: =IF(V23="","",V23/R23) -> 2.8094576 | X23: 1650 | Y23: 1574 | Z23: 1066 | AA23: =IF(SUM(X23:Z23)=0,"",SUM(X23:Z23)) -> 4290 | AB23: =IF(AA23="","",AA23/R23) -> 29.833102 | AC23: =IF(SUM(V23,AA23)=0,"",SUM(V23,AA23)) -> 4694 | AD23: =IF(AC23="","",AC23/R23) -> 32.642559 | AE23: 25 | AF23: 25 | AG23: 0 | AH23: =IF(SUM(AE23:AG23)=0,"",SUM(AE23:AG23)) -> 50 | AI23: =IF(AH23="","",AH23/R23) -> 0.34770515
A24: =IF('09월 조업일지'!A21="","",'09월 조업일지'!A21) -> 46266 | B24: ='09월 조업일지'!E21 -> A | C24: ='09월 조업일지'!F21 -> A | D24: ='09월 화학성분'!C21 -> 85223 | E24: =IF(F24="","",E23) -> S355JO-01 | F24: 19 | G24: 23500 | H24: 18 | I24: 20700 | J24: 7 | K24: 9800 | L24: =IF(ISBLANK(F24),"",SUM(F24,H24,J24)) -> 44 | M24: =IF(ISBLANK(G24),"",SUM(G24,I24,K24)) -> 54000 | N24: =IF(ISBLANK(G24),"",G24/R24) -> 158.99865 | O24: =IF(ISBLANK(I24),"",+I24/R24) -> 140.05413 | P24: =IF(ISBLANK(K24),"",K24/R24) -> 66.305819 | Q24: =IF(ISBLANK(K24),"",SUM(N24:P24)) -> 365.35859 | R24: 147.8 | S24: 0 | T24: 180 | U24: 148 | V24: =IF(SUM(S24:U24)=0,"",SUM(S24:U24)) -> 328 | W24: =IF(V24="","",V24/R24) -> 2.2192152 | X24: 1716 | Y24: 1620 | Z24: 798 | AA24: =IF(SUM(X24:Z24)=0,"",SUM(X24:Z24)) -> 4134 | AB24: =IF(AA24="","",AA24/R24) -> 27.97023 | AC24: =IF(SUM(V24,AA24)=0,"",SUM(V24,AA24)) -> 4462 | AD24: =IF(AC24="","",AC24/R24) -> 30.189445 | AE24: 23 | AF24: 25 | AG24: 0 | AH24: =IF(SUM(AE24:AG24)=0,"",SUM(AE24:AG24)) -> 48 | AI24: =IF(AH24="","",AH24/R24) -> 0.32476319
A25: =IF('09월 조업일지'!A22="","",'09월 조업일지'!A22) -> 46266 | B25: ='09월 조업일지'!E22 -> A | C25: ='09월 조업일지'!F22 -> B | D25: ='09월 화학성분'!C22 -> 85224 | E25: =IF(F25="","",E24) -> S355JO-01 | F25: 21 | G25: 23100 | H25: 18 | I25: 20400 | J25: 9 | K25: 12400 | L25: =IF(ISBLANK(F25),"",SUM(F25,H25,J25)) -> 48 | M25: =IF(ISBLANK(G25),"",SUM(G25,I25,K25)) -> 55900 | N25: =IF(ISBLANK(G25),"",G25/R25) -> 158.54496 | O25: =IF(ISBLANK(I25),"",+I25/R25) -> 140.01373 | P25: =IF(ISBLANK(K25),"",K25/R25) -> 85.106383 | Q25: =IF(ISBLANK(K25),"",SUM(N25:P25)) -> 383.66507 | R25: 145.7 | S25: 0 | T25: 104 | U25: 328 | V25: =IF(SUM(S25:U25)=0,"",SUM(S25:U25)) -> 432 | W25: =IF(V25="","",V25/R25) -> 2.9649966 | X25: 1661 | Y25: 1603 | Z25: 1260 | AA25: =IF(SUM(X25:Z25)=0,"",SUM(X25:Z25)) -> 4524 | AB25: =IF(AA25="","",AA25/R25) -> 31.050103 | AC25: =IF(SUM(V25,AA25)=0,"",SUM(V25,AA25)) -> 4956 | AD25: =IF(AC25="","",AC25/R25) -> 34.0151 | AE25: 23 | AF25: 30 | AG25: 0 | AH25: =IF(SUM(AE25:AG25)=0,"",SUM(AE25:AG25)) -> 53 | AI25: =IF(AH25="","",AH25/R25) -> 0.36376115
A26: =IF('09월 조업일지'!A23="","",'09월 조업일지'!A23) -> 46266 | B26: ='09월 조업일지'!E23 -> A | C26: ='09월 조업일지'!F23 -> A | D26: ='09월 화학성분'!C23 -> 85225 | E26: =IF(F26="","",E25) -> S355JO-01 | F26: 20 | G26: 23700 | H26: 17 | I26: 20700 | J26: 7 | K26: 8900 | L26: =IF(ISBLANK(F26),"",SUM(F26,H26,J26)) -> 44 | M26: =IF(ISBLANK(G26),"",SUM(G26,I26,K26)) -> 53300 | N26: =IF(ISBLANK(G26),"",G26/R26) -> 159.27419 | O26: =IF(ISBLANK(I26),"",+I26/R26) -> 139.1129 | P26: =IF(ISBLANK(K26),"",K26/R26) -> 59.811828 | Q26: =IF(ISBLANK(K26),"",SUM(N26:P26)) -> 358.19892 | R26: 148.8 | S26: 0 | T26: 146 | U26: 167 | V26: =IF(SUM(S26:U26)=0,"",SUM(S26:U26)) -> 313 | W26: =IF(V26="","",V26/R26) -> 2.1034946 | X26: 1715 | Y26: 1577 | Z26: 779 | AA26: =IF(SUM(X26:Z26)=0,"",SUM(X26:Z26)) -> 4071 | AB26: =IF(AA26="","",AA26/R26) -> 27.358871 | AC26: =IF(SUM(V26,AA26)=0,"",SUM(V26,AA26)) -> 4384 | AD26: =IF(AC26="","",AC26/R26) -> 29.462366 | AE26: 27 | AF26: 24 | AG26: 0 | AH26: =IF(SUM(AE26:AG26)=0,"",SUM(AE26:AG26)) -> 51 | AI26: =IF(AH26="","",AH26/R26) -> 0.34274194
A27: =IF('09월 조업일지'!A24="","",'09월 조업일지'!A24) -> 46266 | B27: ='09월 조업일지'!E24 -> A | C27: ='09월 조업일지'!F24 -> B | D27: ='09월 화학성분'!C24 -> 85226 | E27: =IF(F27="","",E26) -> S355JO-01 | F27: 20 | G27: 23200 | H27: 18 | I27: 20600 | J27: 8 | K27: 10800 | L27: =IF(ISBLANK(F27),"",SUM(F27,H27,J27)) -> 46 | M27: =IF(ISBLANK(G27),"",SUM(G27,I27,K27)) -> 54600 | N27: =IF(ISBLANK(G27),"",G27/R27) -> 158.36177 | O27: =IF(ISBLANK(I27),"",+I27/R27) -> 140.61433 | P27: =IF(ISBLANK(K27),"",K27/R27) -> 73.720137 | Q27: =IF(ISBLANK(K27),"",SUM(N27:P27)) -> 372.69625 | R27: 146.5 | S27: 0 | T27: 240 | U27: 84 | V27: =IF(SUM(S27:U27)=0,"",SUM(S27:U27)) -> 324 | W27: =IF(V27="","",V27/R27) -> 2.2116041 | X27: 1638 | Y27: 1599 | Z27: 1021 | AA27: =IF(SUM(X27:Z27)=0,"",SUM(X27:Z27)) -> 4258 | AB27: =IF(AA27="","",AA27/R27) -> 29.064846 | AC27: =IF(SUM(V27,AA27)=0,"",SUM(V27,AA27)) -> 4582 | AD27: =IF(AC27="","",AC27/R27) -> 31.276451 | AE27: 24 | AF27: 26 | AG27: 0 | AH27: =IF(SUM(AE27:AG27)=0,"",SUM(AE27:AG27)) -> 50 | AI27: =IF(AH27="","",AH27/R27) -> 0.34129693
A28: =IF('09월 조업일지'!A25="","",'09월 조업일지'!A25) -> 46266 | B28: ='09월 조업일지'!E25 -> A | C28: ='09월 조업일지'!F25 -> A | D28: ='09월 화학성분'!C25 -> 85227 | E28: =IF(F28="","",E27) -> S355JO-01 | F28: 21 | G28: 23600 | H28: 17 | I28: 20500 | J28: 7 | K28: 8700 | L28: =IF(ISBLANK(F28),"",SUM(F28,H28,J28)) -> 45 | M28: =IF(ISBLANK(G28),"",SUM(G28,I28,K28)) -> 52800 | N28: =IF(ISBLANK(G28),"",G28/R28) -> 165.15045 | O28: =IF(ISBLANK(I28),"",+I28/R28) -> 143.45696 | P28: =IF(ISBLANK(K28),"",K28/R28) -> 60.881735 | Q28: =IF(ISBLANK(K28),"",SUM(N28:P28)) -> 369.48915 | R28: 142.9 | S28: 0 | T28: 103 | U28: 249 | V28: =IF(SUM(S28:U28)=0,"",SUM(S28:U28)) -> 352 | W28: =IF(V28="","",V28/R28) -> 2.463261 | X28: 1746 | Y28: 1570 | Z28: 670 | AA28: =IF(SUM(X28:Z28)=0,"",SUM(X28:Z28)) -> 3986 | AB28: =IF(AA28="","",AA28/R28) -> 27.893632 | AC28: =IF(SUM(V28,AA28)=0,"",SUM(V28,AA28)) -> 4338 | AD28: =IF(AC28="","",AC28/R28) -> 30.356893 | AE28: 25 | AF28: 21 | AG28: 0 | AH28: =IF(SUM(AE28:AG28)=0,"",SUM(AE28:AG28)) -> 46 | AI28: =IF(AH28="","",AH28/R28) -> 0.32190343
A29: =IF('09월 조업일지'!A26="","",'09월 조업일지'!A26) -> 46266 | B29: ='09월 조업일지'!E26 -> C | C29: ='09월 조업일지'!F26 -> B | D29: ='09월 화학성분'!C26 -> 85228 | E29: =IF(F29="","",E28) -> S355JO-01 | F29: 20 | G29: 23600 | H29: 18 | I29: 20500 | J29: 8 | K29: 10000 | L29: =IF(ISBLANK(F29),"",SUM(F29,H29,J29)) -> 46 | M29: =IF(ISBLANK(G29),"",SUM(G29,I29,K29)) -> 54100 | N29: =IF(ISBLANK(G29),"",G29/R29) -> 159.35179 | O29: =IF(ISBLANK(I29),"",+I29/R29) -> 138.41999 | P29: =IF(ISBLANK(K29),"",K29/R29) -> 67.521945 | Q29: =IF(ISBLANK(K29),"",SUM(N29:P29)) -> 365.29372 | R29: 148.1 | S29: 0 | T29: 135 | U29: 215 | V29: =IF(SUM(S29:U29)=0,"",SUM(S29:U29)) -> 350 | W29: =IF(V29="","",V29/R29) -> 2.3632681 | X29: 1725 | Y29: 1595 | Z29: 704 | AA29: =IF(SUM(X29:Z29)=0,"",SUM(X29:Z29)) -> 4024 | AB29: =IF(AA29="","",AA29/R29) -> 27.170831 | AC29: =IF(SUM(V29,AA29)=0,"",SUM(V29,AA29)) -> 4374 | AD29: =IF(AC29="","",AC29/R29) -> 29.534099 | AE29: 25 | AF29: 26 | AG29: 0 | AH29: =IF(SUM(AE29:AG29)=0,"",SUM(AE29:AG29)) -> 51 | AI29: =IF(AH29="","",AH29/R29) -> 0.34436192
A30: =IF('09월 조업일지'!A27="","",'09월 조업일지'!A27) -> 46266 | B30: ='09월 조업일지'!E27 -> C | C30: ='09월 조업일지'!F27 -> A | D30: ='09월 화학성분'!C27 -> 85229 | E30: =IF(F30="","",E29) -> S355JO-01 | F30: 21 | G30: 24000 | H30: 18 | I30: 20600 | J30: 8 | K30: 9700 | L30: =IF(ISBLANK(F30),"",SUM(F30,H30,J30)) -> 47 | M30: =IF(ISBLANK(G30),"",SUM(G30,I30,K30)) -> 54300 | N30: =IF(ISBLANK(G30),"",G30/R30) -> 161.39879 | O30: =IF(ISBLANK(I30),"",+I30/R30) -> 138.53396 | P30: =IF(ISBLANK(K30),"",K30/R30) -> 65.232011 | Q30: =IF(ISBLANK(K30),"",SUM(N30:P30)) -> 365.16476 | R30: 148.7 | S30: 0 | T30: 168 | U30: 167 | V30: =IF(SUM(S30:U30)=0,"",SUM(S30:U30)) -> 335 | W30: =IF(V30="","",V30/R30) -> 2.2528581 | X30: 1806 | Y30: 1717 | Z30: 806 | AA30: =IF(SUM(X30:Z30)=0,"",SUM(X30:Z30)) -> 4329 | AB30: =IF(AA30="","",AA30/R30) -> 29.112307 | AC30: =IF(SUM(V30,AA30)=0,"",SUM(V30,AA30)) -> 4664 | AD30: =IF(AC30="","",AC30/R30) -> 31.365165 | AE30: 27 | AF30: 25 | AG30: 0 | AH30: =IF(SUM(AE30:AG30)=0,"",SUM(AE30:AG30)) -> 52 | AI30: =IF(AH30="","",AH30/R30) -> 0.34969738
A31: =IF('09월 조업일지'!A28="","",'09월 조업일지'!A28) -> 46266 | B31: ='09월 조업일지'!E28 -> C | C31: ='09월 조업일지'!F28 -> B | D31: ='09월 화학성분'!C28 -> 85230 | E31: =IF(F31="","",E30) -> S355JO-01 | F31: 20 | G31: 23800 | H31: 18 | I31: 20500 | J31: 7 | K31: 8800 | L31: =IF(ISBLANK(F31),"",SUM(F31,H31,J31)) -> 45 | M31: =IF(ISBLANK(G31),"",SUM(G31,I31,K31)) -> 53100 | N31: =IF(ISBLANK(G31),"",G31/R31) -> 162.23586 | O31: =IF(ISBLANK(I31),"",+I31/R31) -> 139.74097 | P31: =IF(ISBLANK(K31),"",K31/R31) -> 59.986367 | Q31: =IF(ISBLANK(K31),"",SUM(N31:P31)) -> 361.96319 | R31: 146.7 | S31: 0 | T31: 157 | U31: 224 | V31: =IF(SUM(S31:U31)=0,"",SUM(S31:U31)) -> 381 | W31: =IF(V31="","",V31/R31) -> 2.597137 | X31: 1639 | Y31: 1643 | Z31: 769 | AA31: =IF(SUM(X31:Z31)=0,"",SUM(X31:Z31)) -> 4051 | AB31: =IF(AA31="","",AA31/R31) -> 27.614179 | AC31: =IF(SUM(V31,AA31)=0,"",SUM(V31,AA31)) -> 4432 | AD31: =IF(AC31="","",AC31/R31) -> 30.211316 | AE31: 25 | AF31: 30 | AG31: 0 | AH31: =IF(SUM(AE31:AG31)=0,"",SUM(AE31:AG31)) -> 55 | AI31: =IF(AH31="","",AH31/R31) -> 0.37491479
A32: =IF('09월 조업일지'!A29="","",'09월 조업일지'!A29) -> 46266 | B32: ='09월 조업일지'!E29 -> C | C32: ='09월 조업일지'!F29 -> A | D32: ='09월 화학성분'!C29 -> 85231 | E32: =IF(F32="","",E31) -> S355JO-01 | F32: 20 | G32: 23500 | H32: 16 | I32: 20400 | J32: 8 | K32: 9400 | L32: =IF(ISBLANK(F32),"",SUM(F32,H32,J32)) -> 44 | M32: =IF(ISBLANK(G32),"",SUM(G32,I32,K32)) -> 53300 | N32: =IF(ISBLANK(G32),"",G32/R32) -> 156.87583 | O32: =IF(ISBLANK(I32),"",+I32/R32) -> 136.18158 | P32: =IF(ISBLANK(K32),"",K32/R32) -> 62.750334 | Q32: =IF(ISBLANK(K32),"",SUM(N32:P32)) -> 355.80774 | R32: 149.8 | S32: 0 | T32: 173 | U32: 332 | V32: =IF(SUM(S32:U32)=0,"",SUM(S32:U32)) -> 505 | W32: =IF(V32="","",V32/R32) -> 3.3711615 | X32: 1729 | Y32: 1636 | Z32: 884 | AA32: =IF(SUM(X32:Z32)=0,"",SUM(X32:Z32)) -> 4249 | AB32: =IF(AA32="","",AA32/R32) -> 28.364486 | AC32: =IF(SUM(V32,AA32)=0,"",SUM(V32,AA32)) -> 4754 | AD32: =IF(AC32="","",AC32/R32) -> 31.735648 | AE32: 26 | AF32: 24 | AG32: 0 | AH32: =IF(SUM(AE32:AG32)=0,"",SUM(AE32:AG32)) -> 50 | AI32: =IF(AH32="","",AH32/R32) -> 0.33377837
A33: =IF('09월 조업일지'!A30="","",'09월 조업일지'!A30) -> 46266 | B33: ='09월 조업일지'!E30 -> C | C33: ='09월 조업일지'!F30 -> B | D33: ='09월 화학성분'!C30 -> 85232 | E33: =IF(F33="","",E32) -> S355JO-01 | F33: 20 | G33: 23100 | H33: 16 | I33: 20300 | J33: 8 | K33: 9600 | L33: =IF(ISBLANK(F33),"",SUM(F33,H33,J33)) -> 44 | M33: =IF(ISBLANK(G33),"",SUM(G33,I33,K33)) -> 53000 | N33: =IF(ISBLANK(G33),"",G33/R33) -> 155.13768 | O33: =IF(ISBLANK(I33),"",+I33/R33) -> 136.33311 | P33: =IF(ISBLANK(K33),"",K33/R33) -> 64.472801 | Q33: =IF(ISBLANK(K33),"",SUM(N33:P33)) -> 355.94359 | R33: 148.9 | S33: 0 | T33: 176 | U33: 257 | V33: =IF(SUM(S33:U33)=0,"",SUM(S33:U33)) -> 433 | W33: =IF(V33="","",V33/R33) -> 2.9079919 | X33: 1672 | Y33: 1612 | Z33: 736 | AA33: =IF(SUM(X33:Z33)=0,"",SUM(X33:Z33)) -> 4020 | AB33: =IF(AA33="","",AA33/R33) -> 26.997985 | AC33: =IF(SUM(V33,AA33)=0,"",SUM(V33,AA33)) -> 4453 | AD33: =IF(AC33="","",AC33/R33) -> 29.905977 | AE33: 25 | AF33: 31 | AG33: 0 | AH33: =IF(SUM(AE33:AG33)=0,"",SUM(AE33:AG33)) -> 56 | AI33: =IF(AH33="","",AH33/R33) -> 0.37609134
A34: =IF('09월 조업일지'!A31="","",'09월 조업일지'!A31) -> 46266 | B34: ='09월 조업일지'!E31 -> C | C34: ='09월 조업일지'!F31 -> A | D34: ='09월 화학성분'!C31 -> 85233 | E34: SS400(ToMok) | F34: 19 | G34: 23200 | H34: 18 | I34: 20300 | J34: 7 | K34: 8200 | L34: =IF(ISBLANK(F34),"",SUM(F34,H34,J34)) -> 44 | M34: =IF(ISBLANK(G34),"",SUM(G34,I34,K34)) -> 51700 | N34: =IF(ISBLANK(G34),"",G34/R34) -> 154.76985 | O34: =IF(ISBLANK(I34),"",+I34/R34) -> 135.42362 | P34: =IF(ISBLANK(K34),"",K34/R34) -> 54.703135 | Q34: =IF(ISBLANK(K34),"",SUM(N34:P34)) -> 344.8966 | R34: 149.9 | S34: 0 | T34: 94 | U34: 389 | V34: =IF(SUM(S34:U34)=0,"",SUM(S34:U34)) -> 483 | W34: =IF(V34="","",V34/R34) -> 3.2221481 | X34: 1673 | Y34: 1538 | Z34: 900 | AA34: =IF(SUM(X34:Z34)=0,"",SUM(X34:Z34)) -> 4111 | AB34: =IF(AA34="","",AA34/R34) -> 27.42495 | AC34: =IF(SUM(V34,AA34)=0,"",SUM(V34,AA34)) -> 4594 | AD34: =IF(AC34="","",AC34/R34) -> 30.647098 | AE34: 26 | AF34: 14 | AG34: 0 | AH34: =IF(SUM(AE34:AG34)=0,"",SUM(AE34:AG34)) -> 40 | AI34: =IF(AH34="","",AH34/R34) -> 0.26684456
A35: =IF('09월 조업일지'!A32="","",'09월 조업일지'!A32) -> 46266 | B35: ='09월 조업일지'!E32 -> C | C35: ='09월 조업일지'!F32 -> B | D35: ='09월 화학성분'!C32 -> 85234 | E35: =IF(F35="","",E34) -> SS400(ToMok) | F35: 21 | G35: 23500 | H35: 18 | I35: 20800 | J35: 6 | K35: 6900 | L35: =IF(ISBLANK(F35),"",SUM(F35,H35,J35)) -> 45 | M35: =IF(ISBLANK(G35),"",SUM(G35,I35,K35)) -> 51200 | N35: =IF(ISBLANK(G35),"",G35/R35) -> 157.71812 | O35: =IF(ISBLANK(I35),"",+I35/R35) -> 139.59732 | P35: =IF(ISBLANK(K35),"",K35/R35) -> 46.308725 | Q35: =IF(ISBLANK(K35),"",SUM(N35:P35)) -> 343.62416 | R35: 149 | S35: 0 | T35: 200 | U35: 201 | V35: =IF(SUM(S35:U35)=0,"",SUM(S35:U35)) -> 401 | W35: =IF(V35="","",V35/R35) -> 2.6912752 | X35: 1639 | Y35: 1651 | Z35: 679 | AA35: =IF(SUM(X35:Z35)=0,"",SUM(X35:Z35)) -> 3969 | AB35: =IF(AA35="","",AA35/R35) -> 26.637584 | AC35: =IF(SUM(V35,AA35)=0,"",SUM(V35,AA35)) -> 4370 | AD35: =IF(AC35="","",AC35/R35) -> 29.328859 | AE35: 25 | AF35: 27 | AG35: 0 | AH35: =IF(SUM(AE35:AG35)=0,"",SUM(AE35:AG35)) -> 52 | AI35: =IF(AH35="","",AH35/R35) -> 0.34899329
A36: =IF('09월 조업일지'!A33="","",'09월 조업일지'!A33) -> 46266 | B36: ='09월 조업일지'!E33 -> C | C36: ='09월 조업일지'!F33 -> A | D36: ='09월 화학성분'!C33 -> 85235 | E36: =IF(F36="","",E35) -> SS400(ToMok) | F36: 20 | G36: 23900 | H36: 17 | I36: 20300 | J36: 7 | K36: 8300 | L36: =IF(ISBLANK(F36),"",SUM(F36,H36,J36)) -> 44 | M36: =IF(ISBLANK(G36),"",SUM(G36,I36,K36)) -> 52500 | N36: =IF(ISBLANK(G36),"",G36/R36) -> 161.59567 | O36: =IF(ISBLANK(I36),"",+I36/R36) -> 137.2549 | P36: =IF(ISBLANK(K36),"",K36/R36) -> 56.118999 | Q36: =IF(ISBLANK(K36),"",SUM(N36:P36)) -> 354.96957 | R36: 147.9 | S36: 0 | T36: 172 | U36: 216 | V36: =IF(SUM(S36:U36)=0,"",SUM(S36:U36)) -> 388 | W36: =IF(V36="","",V36/R36) -> 2.6233942 | X36: 1734 | Y36: 1624 | Z36: 706 | AA36: =IF(SUM(X36:Z36)=0,"",SUM(X36:Z36)) -> 4064 | AB36: =IF(AA36="","",AA36/R36) -> 27.478026 | AC36: =IF(SUM(V36,AA36)=0,"",SUM(V36,AA36)) -> 4452 | AD36: =IF(AC36="","",AC36/R36) -> 30.10142 | AE36: 25 | AF36: 27 | AG36: 0 | AH36: =IF(SUM(AE36:AG36)=0,"",SUM(AE36:AG36)) -> 52 | AI36: =IF(AH36="","",AH36/R36) -> 0.35158891
A37: =IF('09월 조업일지'!A34="","",'09월 조업일지'!A34) -> 46266 | B37: ='09월 조업일지'!E34 -> C | C37: ='09월 조업일지'!F34 -> B | D37: ='09월 화학성분'!C34 -> 85236 | E37: =IF(F37="","",E36) -> SS400(ToMok) | F37: 20 | G37: 23300 | H37: 16 | I37: 20400 | J37: 6 | K37: 7600 | L37: =IF(ISBLANK(F37),"",SUM(F37,H37,J37)) -> 42 | M37: =IF(ISBLANK(G37),"",SUM(G37,I37,K37)) -> 51300 | N37: =IF(ISBLANK(G37),"",G37/R37) -> 156.90236 | O37: =IF(ISBLANK(I37),"",+I37/R37) -> 137.37374 | P37: =IF(ISBLANK(K37),"",K37/R37) -> 51.178451 | Q37: =IF(ISBLANK(K37),"",SUM(N37:P37)) -> 345.45455 | R37: 148.5 | S37: 0 | T37: 81 | U37: 306 | V37: =IF(SUM(S37:U37)=0,"",SUM(S37:U37)) -> 387 | W37: =IF(V37="","",V37/R37) -> 2.6060606 | X37: 1676 | Y37: 1632 | Z37: 683 | AA37: =IF(SUM(X37:Z37)=0,"",SUM(X37:Z37)) -> 3991 | AB37: =IF(AA37="","",AA37/R37) -> 26.875421 | AC37: =IF(SUM(V37,AA37)=0,"",SUM(V37,AA37)) -> 4378 | AD37: =IF(AC37="","",AC37/R37) -> 29.481481 | AE37: 25 | AF37: 34 | AG37: 0 | AH37: =IF(SUM(AE37:AG37)=0,"",SUM(AE37:AG37)) -> 59 | AI37: =IF(AH37="","",AH37/R37) -> 0.3973064
A38: =IF('09월 조업일지'!A35="","",'09월 조업일지'!A35) -> 46266 | B38: ='09월 조업일지'!E35 -> C | C38: ='09월 조업일지'!F35 -> A | D38: ='09월 화학성분'!C35 -> 85237 | E38: =IF(F38="","",E37) -> SS400(ToMok) | F38: 21 | G38: 24500 | H38: 18 | I38: 20700 | J38: 7 | K38: 8100 | L38: =IF(ISBLANK(F38),"",SUM(F38,H38,J38)) -> 46 | M38: =IF(ISBLANK(G38),"",SUM(G38,I38,K38)) -> 53300 | N38: =IF(ISBLANK(G38),"",G38/R38) -> 165.98916 | O38: =IF(ISBLANK(I38),"",+I38/R38) -> 140.2439 | P38: =IF(ISBLANK(K38),"",K38/R38) -> 54.878049 | Q38: =IF(ISBLANK(K38),"",SUM(N38:P38)) -> 361.11111 | R38: 147.6 | S38: 0 | T38: 205 | U38: 201 | V38: =IF(SUM(S38:U38)=0,"",SUM(S38:U38)) -> 406 | W38: =IF(V38="","",V38/R38) -> 2.7506775 | X38: 1710 | Y38: 1644 | Z38: 709 | AA38: =IF(SUM(X38:Z38)=0,"",SUM(X38:Z38)) -> 4063 | AB38: =IF(AA38="","",AA38/R38) -> 27.5271 | AC38: =IF(SUM(V38,AA38)=0,"",SUM(V38,AA38)) -> 4469 | AD38: =IF(AC38="","",AC38/R38) -> 30.277778 | AE38: 25 | AF38: 26 | AG38: 0 | AH38: =IF(SUM(AE38:AG38)=0,"",SUM(AE38:AG38)) -> 51 | AI38: =IF(AH38="","",AH38/R38) -> 0.34552846
A39: =IF('09월 조업일지'!A36="","",'09월 조업일지'!A36) -> 46266 | B39: ='09월 조업일지'!E36 -> D | C39: ='09월 조업일지'!F36 -> B | D39: ='09월 화학성분'!C36 -> 85238 | E39: =IF(F39="","",E38) -> SS400(ToMok) | F39: 19 | G39: 23100 | H39: 19 | I39: 20500 | J39: 7 | K39: 9300 | L39: =IF(ISBLANK(F39),"",SUM(F39,H39,J39)) -> 45 | M39: =IF(ISBLANK(G39),"",SUM(G39,I39,K39)) -> 52900 | N39: =IF(ISBLANK(G39),"",G39/R39) -> 157.24983 | O39: =IF(ISBLANK(I39),"",+I39/R39) -> 139.55071 | P39: =IF(ISBLANK(K39),"",K39/R39) -> 63.308373 | Q39: =IF(ISBLANK(K39),"",SUM(N39:P39)) -> 360.10892 | R39: 146.9 | S39: 0 | T39: 199 | U39: 206 | V39: =IF(SUM(S39:U39)=0,"",SUM(S39:U39)) -> 405 | W39: =IF(V39="","",V39/R39) -> 2.7569775 | X39: 1620 | Y39: 1684 | Z39: 795 | AA39: =IF(SUM(X39:Z39)=0,"",SUM(X39:Z39)) -> 4099 | AB39: =IF(AA39="","",AA39/R39) -> 27.903336 | AC39: =IF(SUM(V39,AA39)=0,"",SUM(V39,AA39)) -> 4504 | AD39: =IF(AC39="","",AC39/R39) -> 30.660313 | AE39: 23 | AF39: 30 | AG39: 0 | AH39: =IF(SUM(AE39:AG39)=0,"",SUM(AE39:AG39)) -> 53 | AI39: =IF(AH39="","",AH39/R39) -> 0.36078965
A40: =IF('09월 조업일지'!A37="","",'09월 조업일지'!A37) -> 46266 | B40: ='09월 조업일지'!E37 -> D | C40: ='09월 조업일지'!F37 -> A | D40: ='09월 화학성분'!C37 -> 85239 | E40: =IF(F40="","",E39) -> SS400(ToMok) | F40: 20 | G40: 23100 | H40: 19 | I40: 20400 | J40: 6 | K40: 8700 | L40: =IF(ISBLANK(F40),"",SUM(F40,H40,J40)) -> 45 | M40: =IF(ISBLANK(G40),"",SUM(G40,I40,K40)) -> 52200 | N40: =IF(ISBLANK(G40),"",G40/R40) -> 155.76534 | O40: =IF(ISBLANK(I40),"",+I40/R40) -> 137.559 | P40: =IF(ISBLANK(K40),"",K40/R40) -> 58.664869 | Q40: =IF(ISBLANK(K40),"",SUM(N40:P40)) -> 351.98921 | R40: 148.3 | S40: 0 | T40: 205 | U40: 203 | V40: =IF(SUM(S40:U40)=0,"",SUM(S40:U40)) -> 408 | W40: =IF(V40="","",V40/R40) -> 2.75118 | X40: 1719 | Y40: 1640 | Z40: 717 | AA40: =IF(SUM(X40:Z40)=0,"",SUM(X40:Z40)) -> 4076 | AB40: =IF(AA40="","",AA40/R40) -> 27.484828 | AC40: =IF(SUM(V40,AA40)=0,"",SUM(V40,AA40)) -> 4484 | AD40: =IF(AC40="","",AC40/R40) -> 30.236008 | AE40: 26 | AF40: 28 | AG40: 0 | AH40: =IF(SUM(AE40:AG40)=0,"",SUM(AE40:AG40)) -> 54 | AI40: =IF(AH40="","",AH40/R40) -> 0.36412677
A41: =IF('09월 조업일지'!A38="","",'09월 조업일지'!A38) -> 46266 | B41: ='09월 조업일지'!E38 -> D | C41: ='09월 조업일지'!F38 -> B | D41: ='09월 화학성분'!C38 -> 85240 | E41: =IF(F41="","",E40) -> SS400(ToMok) | F41: 19 | G41: 23500 | H41: 18 | I41: 20600 | J41: 6 | K41: 7900 | L41: =IF(ISBLANK(F41),"",SUM(F41,H41,J41)) -> 43 | M41: =IF(ISBLANK(G41),"",SUM(G41,I41,K41)) -> 52000 | N41: =IF(ISBLANK(G41),"",G41/R41) -> 160.08174 | O41: =IF(ISBLANK(I41),"",+I41/R41) -> 140.32698 | P41: =IF(ISBLANK(K41),"",K41/R41) -> 53.814714 | Q41: =IF(ISBLANK(K41),"",SUM(N41:P41)) -> 354.22343 | R41: 146.8 | S41: 0 | T41: 202 | U41: 200 | V41: =IF(SUM(S41:U41)=0,"",SUM(S41:U41)) -> 402 | W41: =IF(V41="","",V41/R41) -> 2.7384196 | X41: 1680 | Y41: 1634 | Z41: 732 | AA41: =IF(SUM(X41:Z41)=0,"",SUM(X41:Z41)) -> 4046 | AB41: =IF(AA41="","",AA41/R41) -> 27.561308 | AC41: =IF(SUM(V41,AA41)=0,"",SUM(V41,AA41)) -> 4448 | AD41: =IF(AC41="","",AC41/R41) -> 30.299728 | AE41: 24 | AF41: 30 | AG41: 0 | AH41: =IF(SUM(AE41:AG41)=0,"",SUM(AE41:AG41)) -> 54 | AI41: =IF(AH41="","",AH41/R41) -> 0.36784741
...

Sheet a
B1: 로 | C1: Heat No | D1: 강 종 | E1: M1 | G1: M2 | I1: R | K1: 계 | M1: 원단위 | Q1: 출강량 | R1: Lanma 산소 | W1: VLB 및 Burner 산소 | AB1: 산소계 | AD1: VLB 및 Burner 연료
E2: 시간 | F2: 전력 | G2: 시간 | H2: 전력 | I2: 시간 | J2: 전력 | K2: 시간 | L2: 전력 | M2: M1 | N2: M2 | O2: R | P2: 계 | R2: M1 | S2: M2 | T2: R | U2: 계 | V2: 원단위 | W2: M1 | X2: M2 | Y2: R | Z2: 계 | AA2: 원단위 | AB2: 사용량 | AC2: 원단위 | AD2: M1 | AE2: M2 | AF2: R | AG2: 계 | AH2: 원단위
B3: A | C3: 12172 | D3: SS400-01 | E3: 20 | F3: 24000 | G3: 17 | H3: 20600 | I3: 11 | J3: 13400 | K3: 48 | L3: 58000 | M3: 163.82253 | N3: 140.61433 | O3: 91.467577 | P3: 395.90444 | Q3: 146.5 | R3: 0 | S3: 165 | T3: 152 | U3: 317 | V3: 2.1638225 | W3: 1800 | X3: 1617 | Y3: 1162 | Z3: 4579 | AA3: 31.255973 | AB3: 4896 | AC3: 33.419795 | AD3: 23 | AE3: 25 | AF3: 0 | AG3: 48 | AH3: 0.32764505
B4: A | C4: 12174 | D4: SS400-01 | E4: 21 | F4: 23700 | G4: 17 | H4: 20900 | I4: 6 | J4: 8400 | K4: 44 | L4: 53000 | M4: 162.66301 | N4: 143.44544 | O4: 57.652711 | P4: 363.76115 | Q4: 145.7 | R4: 0 | S4: 162 | T4: 151 | U4: 313 | V4: 2.1482498 | W4: 1700 | X4: 1621 | Y4: 678 | Z4: 3999 | AA4: 27.446809 | AB4: 4312 | AC4: 29.595058 | AD4: 25 | AE4: 23 | AF4: 0 | AG4: 48 | AH4: 0.32944406
B5: A | C5: 12176 | D5: SS400-01 | E5: 20 | F5: 23700 | G5: 16 | H5: 20700 | I5: 8 | J5: 10300 | K5: 44 | L5: 54700 | M5: 159.81119 | N5: 139.58193 | O5: 69.45381 | P5: 368.84693 | Q5: 148.3 | R5: 0 | S5: 137 | T5: 181 | U5: 318 | V5: 2.1443021 | W5: 1702 | X5: 1573 | Y5: 872 | Z5: 4147 | AA5: 27.963587 | AB5: 4465 | AC5: 30.107889 | AD5: 25 | AE5: 23 | AF5: 0 | AG5: 48 | AH5: 0.32366824
B6: A | C6: 12178 | D6: SS400-01 | E6: 19 | F6: 22500 | G6: 18 | H6: 20700 | I6: 10 | J6: 12800 | K6: 47 | L6: 56000 | M6: 151.92438 | N6: 139.77043 | O6: 86.428089 | P6: 378.12289 | Q6: 148.1 | R6: 0 | S6: 83 | T6: 237 | U6: 320 | V6: 2.1607022 | W6: 1534 | X6: 1727 | Y6: 1184 | Z6: 4445 | AA6: 30.013504 | AB6: 4765 | AC6: 32.174207 | AD6: 24 | AE6: 25 | AF6: 0 | AG6: 49 | AH6: 0.33085753
B7: A | C7: 12180 | D7: SS400-01 | E7: 19 | F7: 23500 | G7: 17 | H7: 20600 | I7: 7 | J7: 8100 | K7: 43 | L7: 52200 | M7: 160.73871 | N7: 140.90287 | O7: 55.403557 | P7: 357.04514 | Q7: 146.2 | R7: 0 | S7: 101 | T7: 220 | U7: 321 | V7: 2.1956224 | W7: 1650 | X7: 1582 | Y7: 701 | Z7: 3933 | AA7: 26.901505 | AB7: 4254 | AC7: 29.097127 | AD7: 23 | AE7: 25 | AF7: 0 | AG7: 48 | AH7: 0.32831737
B8: A | C8: 12182 | D8: SS400-01 | E8: 20 | F8: 23500 | G8: 18 | H8: 20700 | I8: 7 | J8: 10000 | K8: 45 | L8: 54200 | M8: 158.03631 | N8: 139.20646 | O8: 67.249496 | P8: 364.49227 | Q8: 148.7 | R8: 0 | S8: 101 | T8: 226 | U8: 327 | V8: 2.1990585 | W8: 1680 | X8: 1760 | Y8: 666 | Z8: 4106 | AA8: 27.612643 | AB8: 4433 | AC8: 29.811701 | AD8: 22 | AE8: 26 | AF8: 0 | AG8: 48 | AH8: 0.32279758
B9: A | C9: 12184 | D9: SS400-01 | E9: 21 | F9: 23600 | G9: 16 | H9: 20500 | I9: 5 | J9: 11800 | K9: 42 | L9: 55900 | M9: 163.4349 | N9: 141.96676 | O9: 81.717452 | P9: 387.11911 | Q9: 144.4 | R9: 0 | S9: 80 | T9: 284 | U9: 364 | V9: 2.5207756 | W9: 1718 | X9: 1584 | Y9: 697 | Z9: 3999 | AA9: 27.693906 | AB9: 4363 | AC9: 30.214681 | AD9: 22 | AE9: 24 | AF9: 0 | AG9: 46 | AH9: 0.31855956
B10: A | C10: 12186 | D10: SS400-01 | E10: 20 | F10: 23600 | G10: 18 | H10: 21000 | I10: 10 | J10: 13500 | K10: 48 | L10: 58100 | M10: 159.8916 | N10: 142.27642 | O10: 91.463415 | P10: 393.63144 | Q10: 147.6 | R10: 0 | S10: 63 | T10: 267 | U10: 330 | V10: 2.2357724 | W10: 1769 | X10: 1819 | Y10: 767 | Z10: 4355 | AA10: 29.50542 | AB10: 4685 | AC10: 31.741192 | AD10: 24 | AE10: 20 | AF10: 8 | AG10: 52 | AH10: 0.35230352
E11: =AVERAGE(E3:E10) -> 20 | F11: =AVERAGE(F3:F10) -> 23512.5 | G11: =AVERAGE(G3:G10) -> 17.125 | H11: =AVERAGE(H3:H10) -> 20712.5 | I11: =AVERAGE(I3:I10) -> 8 | J11: =AVERAGE(J3:J10) -> 11037.5 | K11: =AVERAGE(K3:K10) -> 45.125 | L11: =AVERAGE(L3:L10) -> 55262.5 | ... AH11: =AVERAGE(AH3:AH10) -> 0.32919911
B14: 로 | C14: Heat No | D14: 강 종 | E14: M1 | G14: M2 | I14: R | K14: 계 | M14: 원단위 | Q14: 출강량 | R14: Lanma 산소 | W14: VLB 및 Burner 산소 | AB14: 산소계 | AD14: VLB 및 Burner 연료
E15: 시간 | F15: 전력 | G15: 시간 | H15: 전력 | I15: 시간 | J15: 전력 | K15: 시간 | L15: 전력 | M15: M1 | N15: M2 | O15: R | P15: 계 | R15: M1 | S15: M2 | T15: R | U15: 계 | V15: 원단위 | W15: M1 | X15: M2 | Y15: R | Z15: 계 | AA15: 원단위 | AB15: 사용량 | AC15: 원단위 | AD15: M1 | AE15: M2 | AF15: R | AG15: 계 | AH15: 원단위
B16: A | C16: 12188 | D16: SS400-01 | E16: 19 | F16: 23200 | G16: 17 | H16: 20400 | I16: 7 | J16: 8700 | K16: 43 | L16: 52300 | M16: 158.25375 | N16: 139.15416 | O16: 59.345157 | P16: 356.75307 | Q16: 146.6 | R16: 0 | S16: 176 | T16: 191 | U16: 367 | V16: 2.5034106 | W16: 1648 | X16: 1612 | Y16: 597 | Z16: 3857 | AA16: 26.309686 | AB16: 4224 | AC16: 28.813097 | AD16: 25 | AE16: 21 | AF16: 6 | AG16: 52 | AH16: 0.35470668
B17: A | C17: 12190 | D17: SS400-01 | E17: 21 | F17: 23600 | G17: 17 | H17: 20900 | I17: 7 | J17: 9000 | K17: 45 | L17: 53500 | M17: 160.65351 | N17: 142.27366 | O17: 61.266167 | P17: 364.19333 | Q17: 146.9 | R17: 0 | S17: 140 | T17: 202 | U17: 342 | V17: 2.3281144 | W17: 1740 | X17: 1680 | Y17: 652 | Z17: 4072 | AA17: 27.719537 | AB17: 4414 | AC17: 30.047651 | AD17: 22 | AE17: 20 | AF17: 7 | AG17: 49 | AH17: 0.33356025
B18: A | C18: 12192 | D18: SS400-04 | E18: 19 | F18: 24000 | G18: 18 | H18: 20700 | I18: 7 | J18: 9000 | K18: 44 | L18: 53700 | M18: 160.21362 | N18: 138.18425 | O18: 60.080107 | P18: 358.47797 | Q18: 149.8 | R18: 0 | S18: 180 | T18: 229 | U18: 409 | V18: 2.7303071 | W18: 1734 | X18: 1790 | Y18: 664 | Z18: 4188 | AA18: 27.957276 | AB18: 4597 | AC18: 30.687583 | AD18: 25 | AE18: 22 | AF18: 4 | AG18: 51 | AH18: 0.34045394
B19: A | C19: 12194 | D19: SS400-04 | E19: 20 | F19: 23600 | G19: 18 | H19: 20900 | I19: 8 | J19: 10600 | K19: 46 | L19: 55100 | M19: 161.31237 | N19: 142.85714 | O19: 72.453862 | P19: 376.62338 | Q19: 146.3 | R19: 0 | S19: 122 | T19: 249 | U19: 371 | V19: 2.5358852 | W19: 1727 | X19: 1686 | Y19: 808 | Z19: 4221 | AA19: 28.851675 | AB19: 4592 | AC19: 31.38756 | AD19: 24 | AE19: 19 | AF19: 6 | AG19: 49 | AH19: 0.33492823
B20: A | C20: 12196 | D20: SS400-04 | E20: 19 | F20: 23300 | G20: 18 | H20: 20700 | I20: 9 | J20: 10900 | K20: 46 | L20: 54900 | M20: 160.46832 | N20: 142.56198 | O20: 75.068871 | P20: 378.09917 | Q20: 145.2 | R20: 0 | S20: 203 | T20: 140 | U20: 343 | V20: 2.362259 | W20: 1671 | X20: 1618 | Y20: 872 | Z20: 4161 | AA20: 28.657025 | AB20: 4504 | AC20: 31.019284 | AD20: 23 | AE20: 24 | AF20: 0 | AG20: 47 | AH20: 0.32369146
B21: A | C21: 12198 | D21: SS400-04 | E21: 21 | F21: 23500 | G21: 18 | H21: 20500 | I21: 10 | J21: 12600 | K21: 49 | L21: 56600 | M21: 159.64674 | N21: 139.2663 | O21: 85.597826 | P21: 384.51087 | Q21: 147.2 | R21: 0 | S21: 177 | T21: 175 | U21: 352 | V21: 2.3913043 | W21: 1754 | X21: 1595 | Y21: 1110 | Z21: 4459 | AA21: 30.29212 | AB21: 4811 | AC21: 32.683424 | AD21: 23 | AE21: 25 | AF21: 0 | AG21: 48 | AH21: 0.32608696
B22: A | C22: 12200 | D22: SS400-04 | E22: 20 | F22: 23300 | G22: 17 | H22: 20800 | I22: 7 | J22: 8700 | K22: 44 | L22: 52800 | M22: 159.04437 | N22: 141.97952 | O22: 59.385666 | P22: 360.40956 | Q22: 146.5 | R22: 0 | S22: 205 | T22: 141 | U22: 346 | V22: 2.3617747 | W22: 1704 | X22: 1618 | Y22: 710 | Z22: 4032 | AA22: 27.522184 | AB22: 4378 | AC22: 29.883959 | AD22: 25 | AE22: 25 | AF22: 0 | AG22: 50 | AH22: 0.34129693
B23: A | C23: 12202 | D23: SS400-04 | E23: 21 | F23: 24500 | G23: 18 | H23: 20500 | I23: 8 | J23: 10900 | K23: 47 | L23: 55900 | M23: 165.98916 | N23: 138.88889 | O23: 73.848238 | P23: 378.72629 | Q23: 147.6 | R23: 0 | S23: 190 | T23: 174 | U23: 364 | V23: 2.4661247 | W23: 1755 | X23: 1603 | Y23: 880 | Z23: 4238 | AA23: 28.712737 | AB23: 4602 | AC23: 31.178862 | AD23: 23 | AE23: 26 | AF23: 0 | AG23: 49 | AH23: 0.33197832
B24: A | C24: 12204 | D24: SS400-04 | E24: 20 | F24: 23600 | G24: 17 | H24: 20600 | I24: 9 | J24: 11500 | K24: 46 | L24: 55700 | M24: 162.19931 | N24: 141.58076 | O24: 79.037801 | P24: 382.81787 | Q24: 145.5 | R24: 0 | S24: 175 | T24: 181 | U24: 356 | V24: 2.4467354 | W24: 1723 | X24: 1582 | Y24: 872 | Z24: 4177 | AA24: 28.707904 | AB24: 4533 | AC24: 31.154639 | AD24: 23 | AE24: 26 | AF24: 0 | AG24: 49 | AH24: 0.33676976
B25: A | C25: 12206 | D25: SS400-01 | E25: 19 | F25: 23600 | G25: 17 | H25: 20500 | I25: 9 | J25: 11400 | K25: 45 | L25: 55500 | M25: 159.45946 | N25: 138.51351 | O25: 77.027027 | P25: 375 | Q25: 148 | R25: 0 | S25: 145 | T25: 189 | U25: 334 | V25: 2.2567568 | W25: 1687 | X25: 1580 | Y25: 777 | Z25: 4044 | AA25: 27.324324 | AB25: 4378 | AC25: 29.581081 | AD25: 22 | AE25: 26 | AF25: 0 | AG25: 48 | AH25: 0.32432432
E26: =AVERAGE(E16:E25) -> 19.9 | F26: =AVERAGE(F16:F25) -> 23620 | G26: =AVERAGE(G16:G25) -> 17.5 | H26: =AVERAGE(H16:H25) -> 20650 | I26: =AVERAGE(I16:I25) -> 8.1 | J26: =AVERAGE(J16:J25) -> 10330 | K26: =AVERAGE(K16:K25) -> 45.5 | L26: =AVERAGE(L16:L25) -> 54600 | ... AH26: =AVERAGE(AH16:AH25) -> 0.33477968
E32: 11. 21
E33: Smart Arc Off | F33: A | S33: Yesterday | T33: A
F34: POT | G34: =K11 -> 45.125 | T34: POT | U34: 45.933333
F35: kwh/T | G35: =P11 -> 376.11542 | T35: kwh/T | U35: 372.04366
F36: kwh/Heat | G36: =L11 -> 55262.5 | T36: kwh/Heat | U36: 54820
F37: Tapping | G37: =Q11 -> 146.9375 | T37: Tapping | U37: 147.4
F38: B | T38: B
F39: POT | G39: =B!K11 -> 44.75 | T39: POT | U39: 45.7
F40: kwh/T | G40: =B!P11 -> 360.55091 | T40: kwh/T | U40: 370
F41: kwh/Heat | G41: =B!L11 -> 52875 | T41: kwh/Heat | U41: 54273
F42: Tapping | G42: =B!Q11 -> 146.65 | T42: Tapping | U42: 146.6
E43: Smart Arc On | F43: A | S43: Today | T43: A
F44: POT | G44: =K26 -> 45.5 | T44: POT | U44: 45.75
F45: kwh/T | G45: =P26 -> 371.56115 | T45: kwh/T | U45: 376.65885
F46: kwh/Heat | G46: =L26 -> 54600 | T46: kwh/Heat | U46: 55425
F47: Tapping | G47: =Q26 -> 146.96 | T47: Tapping | U47: 147.15
...

Sheet B
B1: 로 | C1: Heat No | D1: 강 종 | E1: M1 | G1: M2 | I1: R | K1: 계 | M1: 원단위 | Q1: 출강량 | R1: Lanma 산소 | W1: VLB 및 Burner 산소 | AB1: 산소계 | AD1: VLB 및 Burner 연료
E2: 시간 | F2: 전력 | G2: 시간 | H2: 전력 | I2: 시간 | J2: 전력 | K2: 시간 | L2: 전력 | M2: M1 | N2: M2 | O2: R | P2: 계 | R2: M1 | S2: M2 | T2: R | U2: 계 | V2: 원단위 | W2: M1 | X2: M2 | Y2: R | Z2: 계 | AA2: 원단위 | AB2: 사용량 | AC2: 원단위 | AD2: M1 | AE2: M2 | AF2: R | AG2: 계 | AH2: 원단위
B3: B | C3: 12171 | D3: SS400-01 | E3: 21 | F3: 23600 | G3: 18 | H3: 21000 | I3: 6 | J3: 7400 | K3: 45 | L3: 52000 | M3: 161.97666 | N3: 144.13178 | O3: 50.789293 | P3: 356.89774 | Q3: 145.7 | R3: 0 | S3: 185 | T3: 140 | U3: 325 | V3: 2.2306108 | W3: 1773 | X3: 1691 | Y3: 695 | Z3: 4159 | AA3: 28.544955 | AB3: 4484 | AC3: 30.775566 | AD3: 26 | AE3: 29 | AF3: 0 | AG3: 55 | AH3: 0.37748799
B4: B | C4: 12173 | D4: SS400-01 | E4: 19 | F4: 23400 | G4: 18 | H4: 20700 | I4: 7 | J4: 8900 | K4: 44 | L4: 53000 | M4: 158.64407 | N4: 140.33898 | O4: 60.338983 | P4: 359.32203 | Q4: 147.5 | R4: 0 | S4: 190 | T4: 118 | U4: 308 | V4: 2.0881356 | W4: 1691 | X4: 1671 | Y4: 860 | Z4: 4222 | AA4: 28.623729 | AB4: 4530 | AC4: 30.711864 | AD4: 21 | AE4: 30 | AF4: 0 | AG4: 51 | AH4: 0.34576271
B5: B | C5: 12175 | D5: SS400-01 | E5: 20 | F5: 23400 | G5: 16 | H5: 20600 | I5: 7 | J5: 9100 | K5: 43 | L5: 53100 | M5: 161.82573 | N5: 142.46196 | O5: 62.932227 | P5: 367.21992 | Q5: 144.6 | R5: 0 | S5: 81 | T5: 253 | U5: 334 | V5: 2.3098202 | W5: 1683 | X5: 1613 | Y5: 737 | Z5: 4033 | AA5: 27.890733 | AB5: 4367 | AC5: 30.200553 | AD5: 24 | AE5: 27 | AF5: 0 | AG5: 51 | AH5: 0.3526971
B6: B | C6: 12177 | D6: SS400-01 | E6: 20 | F6: 23500 | G6: 18 | H6: 20900 | I6: 7 | J6: 9300 | K6: 45 | L6: 53700 | M6: 159.64674 | N6: 141.9837 | O6: 63.179348 | P6: 364.80978 | Q6: 147.2 | R6: 0 | S6: 237 | T6: 69 | U6: 306 | V6: 2.0788043 | W6: 1815 | X6: 1642 | Y6: 744 | Z6: 4201 | AA6: 28.539402 | AB6: 4507 | AC6: 30.618207 | AD6: 24 | AE6: 28 | AF6: 0 | AG6: 52 | AH6: 0.35326087
B7: B | C7: 12179 | D7: SS400-01 | E7: 21 | F7: 23300 | G7: 18 | H7: 20500 | I7: 8 | J7: 10600 | K7: 47 | L7: 54400 | M7: 157.85908 | N7: 138.88889 | O7: 71.815718 | P7: 368.56369 | Q7: 147.6 | R7: 0 | S7: 167 | T7: 143 | U7: 310 | V7: 2.100271 | W7: 1802 | X7: 1645 | Y7: 1047 | Z7: 4494 | AA7: 30.447154 | AB7: 4804 | AC7: 32.547425 | AD7: 24 | AE7: 27 | AF7: 0 | AG7: 51 | AH7: 0.34552846
B8: B | C8: 12181 | D8: SS400-01 | E8: 21 | F8: 23700 | G8: 19 | H8: 21100 | I8: 4 | J8: 5500 | K8: 44 | L8: 50300 | M8: 161.22449 | N8: 143.53741 | O8: 37.414966 | P8: 342.17687 | Q8: 147 | R8: 0 | S8: 229 | T8: 94 | U8: 323 | V8: 2.1972789 | W8: 1770 | X8: 1736 | Y8: 518 | Z8: 4024 | AA8: 27.37415 | AB8: 4347 | AC8: 29.571429 | AD8: 22 | AE8: 29 | AF8: 0 | AG8: 51 | AH8: 0.34693878
B9: B | C9: 12183 | D9: SS400-01 | E9: 20 | F9: 23500 | G9: 17 | H9: 20700 | I9: 6 | J9: 6800 | K9: 43 | L9: 51000 | M9: 160.40956 | N9: 141.29693 | O9: 46.416382 | P9: 348.12287 | Q9: 146.5 | R9: 0 | S9: 131 | T9: 216 | U9: 347 | V9: 2.3686007 | W9: 1737 | X9: 1607 | Y9: 536 | Z9: 3880 | AA9: 26.484642 | AB9: 4227 | AC9: 28.853242 | AD9: 22 | AE9: 29 | AF9: 0 | AG9: 51 | AH9: 0.34812287
B10: B | C10: 12185 | D10: SS400-01 | E10: 22 | F10: 23600 | G10: 17 | H10: 20600 | I10: 8 | J10: 11300 | K10: 47 | L10: 55500 | M10: 160.43508 | N10: 140.04079 | O10: 76.818491 | P10: 377.29436 | Q10: 147.1 | R10: 0 | S10: 145 | T10: 188 | U10: 333 | V10: 2.2637661 | W10: 1912 | X10: 1575 | Y10: 630 | Z10: 4117 | AA10: 27.987763 | AB10: 4450 | AC10: 30.25153 | AD10: 30 | AE10: 15 | AF10: 5 | AG10: 50 | AH10: 0.33990483
E11: =AVERAGE(E3:E10) -> 20.5 | F11: =AVERAGE(F3:F10) -> 23500 | G11: =AVERAGE(G3:G10) -> 17.625 | H11: =AVERAGE(H3:H10) -> 20762.5 | I11: =AVERAGE(I3:I10) -> 6.625 | J11: =AVERAGE(J3:J10) -> 8612.5 | K11: =AVERAGE(K3:K10) -> 44.75 | L11: =AVERAGE(L3:L10) -> 52875 | ... AH11: =AVERAGE(AH3:AH10) -> 0.35121295
B14: 로 | C14: Heat No | D14: 강 종 | E14: M1 | G14: M2 | I14: R | K14: 계 | M14: 원단위 | Q14: 출강량 | R14: Lanma 산소 | W14: VLB 및 Burner 산소 | AB14: 산소계 | AD14: VLB 및 Burner 연료
E15: 시간 | F15: 전력 | G15: 시간 | H15: 전력 | I15: 시간 | J15: 전력 | K15: 시간 | L15: 전력 | M15: M1 | N15: M2 | O15: R | P15: 계 | R15: M1 | S15: M2 | T15: R | U15: 계 | V15: 원단위 | W15: M1 | X15: M2 | Y15: R | Z15: 계 | AA15: 원단위 | AB15: 사용량 | AC15: 원단위 | AD15: M1 | AE15: M2 | AF15: R | AG15: 계 | AH15: 원단위
B16: B | C16: 12187 | D16: SS400-01 | E16: 21 | F16: 23900 | G16: 17 | H16: 20800 | I16: 8 | J16: 10700 | K16: 46 | L16: 55400 | M16: 161.81449 | N16: 140.826 | O16: 72.444144 | P16: 375.08463 | Q16: 147.7 | R16: 0 | S16: 247 | T16: 191 | U16: 438 | V16: 2.9654705 | W16: 1796 | X16: 1730 | Y16: 634 | Z16: 4160 | AA16: 28.1652 | AB16: 4598 | AC16: 31.13067 | AD16: 18 | AE16: 16 | AF16: 5 | AG16: 39 | AH16: 0.26404875
B17: B | C17: 12189 | D17: SS400-01 | E17: 20 | F17: 23300 | G17: 18 | H17: 20700 | I17: 7 | J17: 9400 | K17: 45 | L17: 53400 | M17: 157.64547 | N17: 140.05413 | O17: 63.599459 | P17: 361.29905 | Q17: 147.8 | R17: 0 | S17: 219 | T17: 158 | U17: 377 | V17: 2.5507442 | W17: 1708 | X17: 1644 | Y17: 605 | Z17: 3957 | AA17: 26.772666 | AB17: 4334 | AC17: 29.32341 | AD17: 18 | AE17: 19 | AF17: 6 | AG17: 43 | AH17: 0.29093369
B18: B | C18: 12191 | D18: SS400-01 | E18: 21 | F18: 24000 | G18: 17 | H18: 21000 | I18: 6 | J18: 8000 | K18: 44 | L18: 53000 | M18: 161.94332 | N18: 141.7004 | O18: 53.981107 | P18: 357.62483 | Q18: 148.2 | R18: 0 | S18: 228 | T18: 142 | U18: 370 | V18: 2.4966262 | W18: 1685 | X18: 1631 | Y18: 533 | Z18: 3849 | AA18: 25.97166 | AB18: 4219 | AC18: 28.468286 | AD18: 18 | AE18: 20 | AF18: 5 | AG18: 43 | AH18: 0.29014845
